Workbook

Sheet Standard Curve
E1: Well | F1: Fluor | G1: Target | H1: Content | I1: Ct Machine | J1: Ct Mean Machine | K1: Ct Std. Dev Machine | L1: Starting Quantity (SQ) CPR Machine | M1: Log Starting Quantity Machine | N1: Run File
F2: FAM | H2: NA026 | L2: 1000000 | M2: =LOG(L2) -> 6
F3: FAM | H3: NA026 | L3: 1000000 | M3: =LOG(L3) -> 6
F4: FAM | H4: NA015 | L4: 100000 | M4: =LOG(L4) -> 5
F5: FAM | H5: NA015 | L5: 100000 | M5: =LOG(L5) -> 5
F6: FAM | H6: NA015 | L6: 100000 | M6: =LOG(L6) -> 5
F7: FAM | H7: NA015 | L7: 100000 | M7: =LOG(L7) -> 5
F8: FAM | H8: NA014 | L8: 10000 | M8: =LOG(L8) -> 4
F9: FAM | H9: NA014 | L9: 10000 | M9: =LOG(L9) -> 4
F10: FAM | H10: NA014 | L10: 10000 | M10: =LOG(L10) -> 4
F11: FAM | H11: NA014 | L11: 10000 | M11: =LOG(L11) -> 4
F12: FAM | H12: NA013 | L12: 1000 | M12: =LOG(L12) -> 3
F13: FAM | H13: NA013 | L13: 1000 | M13: =LOG(L13) -> 3
... F15: FAM | H15: NA012 | L15: 100 | M15: =LOG(L15) -> 2
A16: Std Curve Metrics | B16: Values | C16: Criteria
A17: % Efficiency | B17: =IF(E2="","",((10^(-1/B19))-1)*100) | C17: 90<%Efficiency<110 | D17: =IF(AND(B17>90, B17<110),"Pass","FAIL") -> FAIL
A18: r^2 | B18: =IF(E2="","",RSQ($I$2:$I$494,$M$2:$M$494)) | C18: r^2 | D18: =IF(B18>0.985,"Pass","FAIL") -> Pass
A19: Slope | B19: =IF(E2="","",SLOPE($I$2:$I$494,$M$2:$M$494))
A20: y-intercept | B20: =IF(E2="","",INTERCEPT($I$2:$I$494,$M$2:$M$494))
A21: Assay | B21: Phytoxigene Total Cyano

Sheet Outlier Check
B1: Well | C1: Fluor | D1: Target | E1: Content | F1: Ct Machine | G1: Ct Mean Machine | H1: Ct Std. Dev Machine | I1: Starting Quantity (SQ) CPR Machine | J1: Log Starting Quantity Machine | K1: Run File | L1: Ct Average (All Runs) | M1: Ct Std. Dev Machine (All Runs) | N1: tau | O1: Test 1 | P1: Test 2 | Q1: Test 3 | R1: Test 4
C2: FAM | E2: NA026 | I2: 1000000 | J2: =LOG(I2) -> 6 | L2: =IF(ISNUMBER(F2),AVERAGE($F$2:$F$11),"") | M2: =IF(ISNUMBER(F2),STDEV($F$2:$F$11),"") | N2: =IF(ISNUMBER(G2),VLOOKUP(VALUE(COUNTIF($E$2:$E$11,"NA026")),$T$2:$U$27,2),"") | O2: =IF(ISNUMBER(F2),IF(ABS(L2-F2)<1,"PASS","FAIL"),"") | P2: =IF(ISNUMBER(F2),IF((L2-F2)-(N2*M2)<0,"PASS","FAIL"),"") | Q2: =IF(ISNUMBER(F2),IF(G2>(L2+(M2*3)),"FAIL","PASS"),"") | R2: =IF(ISNUMBER(F2),IF(G2<(L2-(M2*3)),"FAIL","PASS"),"") | T2: n | U2: tau
C3: FAM | E3: NA026 | I3: 1000000 | J3: =LOG(I3) -> 6 | L3: =IF(ISNUMBER(F3),AVERAGE($F$2:$F$11),"") | M3: =IF(ISNUMBER(F3),STDEV($F$2:$F$11),"") | N3: =IF(ISNUMBER(G3),VLOOKUP(VALUE(COUNTIF($E$2:$E$11,"NA026")),$T$2:$U$27,2),"") | O3: =IF(ISNUMBER(F3),IF(ABS(L3-F3)<1,"PASS","FAIL"),"") | P3: =IF(ISNUMBER(F3),IF((L3-F3)-(N3*M3)<0,"PASS","FAIL"),"") | Q3: =IF(ISNUMBER(F3),IF(G3>(L3+(M3*3)),"FAIL","PASS"),"") | R3: =IF(ISNUMBER(F3),IF(G3<(L3-(M3*3)),"FAIL","PASS"),"") | T3: 3 | U3: 1.1511
L4: =IF(ISNUMBER(F4),AVERAGE($F$2:$F$11),"") | M4: =IF(ISNUMBER(F4),STDEV($F$2:$F$11),"") | N4: =IF(ISNUMBER(G4),VLOOKUP(VALUE(COUNTIF($E$2:$E$11,"NA026")),$T$2:$U$27,2),"") | O4: =IF(ISNUMBER(F4),IF(ABS(L4-F4)<1,"PASS","FAIL"),"") | P4: =IF(ISNUMBER(F4),IF((L4-F4)-(N4*M4)<0,"PASS","FAIL"),"") | Q4: =IF(ISNUMBER(F4),IF(G4>(L4+(M4*3)),"FAIL","PASS"),"") | R4: =IF(ISNUMBER(F4),IF(G4<(L4-(M4*3)),"FAIL","PASS"),"") | T4: 4 | U4: 1.425
L5: =IF(ISNUMBER(F5),AVERAGE($F$2:$F$11),"") | M5: =IF(ISNUMBER(F5),STDEV($F$2:$F$11),"") | N5: =IF(ISNUMBER(G5),VLOOKUP(VALUE(COUNTIF($E$2:$E$11,"NA026")),$T$2:$U$27,2),"") | O5: =IF(ISNUMBER(F5),IF(ABS(L5-F5)<1,"PASS","FAIL"),"") | P5: =IF(ISNUMBER(F5),IF((L5-F5)-(N5*M5)<0,"PASS","FAIL"),"") | Q5: =IF(ISNUMBER(F5),IF(G5>(L5+(M5*3)),"FAIL","PASS"),"") | R5: =IF(ISNUMBER(F5),IF(G5<(L5-(M5*3)),"FAIL","PASS"),"") | T5: 5 | U5: 1.5712
A6: NA026 | L6: =IF(ISNUMBER(F6),AVERAGE($F$2:$F$11),"") | M6: =IF(ISNUMBER(F6),STDEV($F$2:$F$11),"") | N6: =IF(ISNUMBER(G6),VLOOKUP(VALUE(COUNTIF($E$2:$E$11,"NA026")),$T$2:$U$27,2),"") | O6: =IF(ISNUMBER(F6),IF(ABS(L6-F6)<1,"PASS","FAIL"),"") | P6: =IF(ISNUMBER(F6),IF((L6-F6)-(N6*M6)<0,"PASS","FAIL"),"") | Q6: =IF(ISNUMBER(F6),IF(G6>(L6+(M6*3)),"FAIL","PASS"),"") | R6: =IF(ISNUMBER(F6),IF(G6<(L6-(M6*3)),"FAIL","PASS"),"") | T6: 6 | U6: 1.6563
A7: ONLY | L7: =IF(ISNUMBER(F7),AVERAGE($F$2:$F$11),"") | M7: =IF(ISNUMBER(F7),STDEV($F$2:$F$11),"") | N7: =IF(ISNUMBER(G7),VLOOKUP(VALUE(COUNTIF($E$2:$E$11,"NA026")),$T$2:$U$27,2),"") | O7: =IF(ISNUMBER(F7),IF(ABS(L7-F7)<1,"PASS","FAIL"),"") | P7: =IF(ISNUMBER(F7),IF((L7-F7)-(N7*M7)<0,"PASS","FAIL"),"") | Q7: =IF(ISNUMBER(F7),IF(G7>(L7+(M7*3)),"FAIL","PASS"),"") | R7: =IF(ISNUMBER(F7),IF(G7<(L7-(M7*3)),"FAIL","PASS"),"") | T7: 7 | U7: 1.711
L8: =IF(ISNUMBER(F8),AVERAGE($F$2:$F$11),"") | M8: =IF(ISNUMBER(F8),STDEV($F$2:$F$11),"") | N8: =IF(ISNUMBER(G8),VLOOKUP(VALUE(COUNTIF($E$2:$E$11,"NA026")),$T$2:$U$27,2),"") | O8: =IF(ISNUMBER(F8),IF(ABS(L8-F8)<1,"PASS","FAIL"),"") | P8: =IF(ISNUMBER(F8),IF((L8-F8)-(N8*M8)<0,"PASS","FAIL"),"") | Q8: =IF(ISNUMBER(F8),IF(G8>(L8+(M8*3)),"FAIL","PASS"),"") | R8: =IF(ISNUMBER(F8),IF(G8<(L8-(M8*3)),"FAIL","PASS"),"") | T8: 8 | U8: 1.7491
L9: =IF(ISNUMBER(F9),AVERAGE($F$2:$F$11),"") | M9: =IF(ISNUMBER(F9),STDEV($F$2:$F$11),"") | N9: =IF(ISNUMBER(G9),VLOOKUP(VALUE(COUNTIF($E$2:$E$11,"NA026")),$T$2:$U$27,2),"") | O9: =IF(ISNUMBER(F9),IF(ABS(L9-F9)<1,"PASS","FAIL"),"") | P9: =IF(ISNUMBER(F9),IF((L9-F9)-(N9*M9)<0,"PASS","FAIL"),"") | Q9: =IF(ISNUMBER(F9),IF(G9>(L9+(M9*3)),"FAIL","PASS"),"") | R9: =IF(ISNUMBER(F9),IF(G9<(L9-(M9*3)),"FAIL","PASS"),"") | T9: 9 | U9: 1.777
L10: =IF(ISNUMBER(F10),AVERAGE($F$2:$F$11),"") | M10: =IF(ISNUMBER(F10),STDEV($F$2:$F$11),"") | N10: =IF(ISNUMBER(G10),VLOOKUP(VALUE(COUNTIF($E$2:$E$11,"NA026")),$T$2:$U$27,2),"") | O10: =IF(ISNUMBER(F10),IF(ABS(L10-F10)<1,"PASS","FAIL"),"") | P10: =IF(ISNUMBER(F10),IF((L10-F10)-(N10*M10)<0,"PASS","FAIL"),"") | Q10: =IF(ISNUMBER(F10),IF(G10>(L10+(M10*3)),"FAIL","PASS"),"") | R10: =IF(ISNUMBER(F10),IF(G10<(L10-(M10*3)),"FAIL","PASS"),"") | T10: 10 | U10: 1.7984
L11: =IF(ISNUMBER(F11),AVERAGE($F$2:$F$11),"") | M11: =IF(ISNUMBER(F11),STDEV($F$2:$F$11),"") | N11: =IF(ISNUMBER(G11),VLOOKUP(VALUE(COUNTIF($E$2:$E$11,"NA026")),$T$2:$U$27,2),"") | O11: =IF(ISNUMBER(F11),IF(ABS(L11-F11)<1,"PASS","FAIL"),"") | P11: =IF(ISNUMBER(F11),IF((L11-F11)-(N11*M11)<0,"PASS","FAIL"),"") | Q11: =IF(ISNUMBER(F11),IF(G11>(L11+(M11*3)),"FAIL","PASS"),"") | R11: =IF(ISNUMBER(F11),IF(G11<(L11-(M11*3)),"FAIL","PASS"),"") | T11: 12 | U11: 1.829
C12: FAM | E12: NA015 | I12: 100000 | J12: =LOG(I12) -> 5 | L12: =IF(ISNUMBER(F12),AVERAGE($F$12:$F$21),"") | M12: =IF(ISNUMBER(F12),STDEV($F$12:$F$21),"") | N12: =IF(ISNUMBER(G12),VLOOKUP(VALUE(COUNTIF($E$12:$E$21,"NA015")),$T$2:$U$27,2),"") | O12: =IF(ISNUMBER(F12),IF(ABS(L12-F12)<1,"PASS","FAIL"),"") | P12: =IF(ISNUMBER(F12),IF((L12-F12)-(N12*M12)<0,"PASS","FAIL"),"") | Q12: =IF(ISNUMBER(F12),IF(G12>(L12+(M12*3)),"FAIL","PASS"),"") | R12: =IF(ISNUMBER(F12),IF(G12<(L12-(M12*3)),"FAIL","PASS"),"") | T12: 14 | U12: 1.8498
C13: FAM | E13: NA015 | I13: 100000 | J13: =LOG(I13) -> 5 | L13: =IF(ISNUMBER(F13),AVERAGE($F$12:$F$21),"") | M13: =IF(ISNUMBER(F13),STDEV($F$12:$F$21),"") | N13: =IF(ISNUMBER(G13),VLOOKUP(VALUE(COUNTIF($E$12:$E$21,"NA015")),$T$2:$U$27,2),"") | O13: =IF(ISNUMBER(F13),IF(ABS(L13-F13)<1,"PASS","FAIL"),"") | P13: =IF(ISNUMBER(F13),IF((L13-F13)-(N13*M13)<0,"PASS","FAIL"),"") | Q13: =IF(ISNUMBER(F13),IF(G13>(L13+(M13*3)),"FAIL","PASS"),"") | R13: =IF(ISNUMBER(F13),IF(G13<(L13-(M13*3)),"FAIL","PASS"),"") | T13: 15 | U13: 1.8579
C14: FAM | E14: NA015 | I14: 100000 | J14: =LOG(I14) -> 5 | L14: =IF(ISNUMBER(F14),AVERAGE($F$12:$F$21),"") | M14: =IF(ISNUMBER(F14),STDEV($F$12:$F$21),"") | N14: =IF(ISNUMBER(G14),VLOOKUP(VALUE(COUNTIF($E$12:$E$21,"NA015")),$T$2:$U$27,2),"") | O14: =IF(ISNUMBER(F14),IF(ABS(L14-F14)<1,"PASS","FAIL"),"") | P14: =IF(ISNUMBER(F14),IF((L14-F14)-(N14*M14)<0,"PASS","FAIL"),"") | Q14: =IF(ISNUMBER(F14),IF(G14>(L14+(M14*3)),"FAIL","PASS"),"") | R14: =IF(ISNUMBER(F14),IF(G14<(L14-(M14*3)),"FAIL","PASS"),"") | T14: 16 | U14: 1.8649
C15: FAM | E15: NA015 | I15: 100000 | J15: =LOG(I15) -> 5 | L15: =IF(ISNUMBER(F15),AVERAGE($F$12:$F$21),"") | M15: =IF(ISNUMBER(F15),STDEV($F$12:$F$21),"") | N15: =IF(ISNUMBER(G15),VLOOKUP(VALUE(COUNTIF($E$12:$E$21,"NA015")),$T$2:$U$27,2),"") | O15: =IF(ISNUMBER(F15),IF(ABS(L15-F15)<1,"PASS","FAIL"),"") | P15: =IF(ISNUMBER(F15),IF((L15-F15)-(N15*M15)<0,"PASS","FAIL"),"") | Q15: =IF(ISNUMBER(F15),IF(G15>(L15+(M15*3)),"FAIL","PASS"),"") | R15: =IF(ISNUMBER(F15),IF(G15<(L15-(M15*3)),"FAIL","PASS"),"") | T15: 18 | U15: 1.8764
A16: NA015 | L16: =IF(ISNUMBER(F16),AVERAGE($F$12:$F$21),"") | M16: =IF(ISNUMBER(F16),STDEV($F$12:$F$21),"") | N16: =IF(ISNUMBER(G16),VLOOKUP(VALUE(COUNTIF($E$12:$E$21,"NA015")),$T$2:$U$27,2),"") | O16: =IF(ISNUMBER(F16),IF(ABS(L16-F16)<1,"PASS","FAIL"),"") | P16: =IF(ISNUMBER(F16),IF((L16-F16)-(N16*M16)<0,"PASS","FAIL"),"") | Q16: =IF(ISNUMBER(F16),IF(G16>(L16+(M16*3)),"FAIL","PASS"),"") | R16: =IF(ISNUMBER(F16),IF(G16<(L16-(M16*3)),"FAIL","PASS"),"") | T16: 19 | U16: 1.8811
A17: ONLY | L17: =IF(ISNUMBER(F17),AVERAGE($F$12:$F$21),"") | M17: =IF(ISNUMBER(F17),STDEV($F$12:$F$21),"") | N17: =IF(ISNUMBER(G17),VLOOKUP(VALUE(COUNTIF($E$12:$E$21,"NA015")),$T$2:$U$27,2),"") | O17: =IF(ISNUMBER(F17),IF(ABS(L17-F17)<1,"PASS","FAIL"),"") | P17: =IF(ISNUMBER(F17),IF((L17-F17)-(N17*M17)<0,"PASS","FAIL"),"") | Q17: =IF(ISNUMBER(F17),IF(G17>(L17+(M17*3)),"FAIL","PASS"),"") | R17: =IF(ISNUMBER(F17),IF(G17<(L17-(M17*3)),"FAIL","PASS"),"") | T17: 20 | U17: 1.8853
L18: =IF(ISNUMBER(F18),AVERAGE($F$12:$F$21),"") | M18: =IF(ISNUMBER(F18),STDEV($F$12:$F$21),"") | N18: =IF(ISNUMBER(G18),VLOOKUP(VALUE(COUNTIF($E$12:$E$21,"NA015")),$T$2:$U$27,2),"") | O18: =IF(ISNUMBER(F18),IF(ABS(L18-F18)<1,"PASS","FAIL"),"") | P18: =IF(ISNUMBER(F18),IF((L18-F18)-(N18*M18)<0,"PASS","FAIL"),"") | Q18: =IF(ISNUMBER(F18),IF(G18>(L18+(M18*3)),"FAIL","PASS"),"") | R18: =IF(ISNUMBER(F18),IF(G18<(L18-(M18*3)),"FAIL","PASS"),"") | T18: 21 | U18: 1.8891
L19: =IF(ISNUMBER(F19),AVERAGE($F$12:$F$21),"") | M19: =IF(ISNUMBER(F19),STDEV($F$12:$F$21),"") | N19: =IF(ISNUMBER(G19),VLOOKUP(VALUE(COUNTIF($E$12:$E$21,"NA015")),$T$2:$U$27,2),"") | O19: =IF(ISNUMBER(F19),IF(ABS(L19-F19)<1,"PASS","FAIL"),"") | P19: =IF(ISNUMBER(F19),IF((L19-F19)-(N19*M19)<0,"PASS","FAIL"),"") | Q19: =IF(ISNUMBER(F19),IF(G19>(L19+(M19*3)),"FAIL","PASS"),"") | R19: =IF(ISNUMBER(F19),IF(G19<(L19-(M19*3)),"FAIL","PASS"),"") | T19: 22 | U19: 1.8926
L20: =IF(ISNUMBER(F20),AVERAGE($F$12:$F$21),"") | M20: =IF(ISNUMBER(F20),STDEV($F$12:$F$21),"") | N20: =IF(ISNUMBER(G20),VLOOKUP(VALUE(COUNTIF($E$12:$E$21,"NA015")),$T$2:$U$27,2),"") | O20: =IF(ISNUMBER(F20),IF(ABS(L20-F20)<1,"PASS","FAIL"),"") | P20: =IF(ISNUMBER(F20),IF((L20-F20)-(N20*M20)<0,"PASS","FAIL"),"") | Q20: =IF(ISNUMBER(F20),IF(G20>(L20+(M20*3)),"FAIL","PASS"),"") | R20: =IF(ISNUMBER(F20),IF(G20<(L20-(M20*3)),"FAIL","PASS"),"") | T20: 23 | U20: 1.8957
L21: =IF(ISNUMBER(F21),AVERAGE($F$12:$F$21),"") | M21: =IF(ISNUMBER(F21),STDEV($F$12:$F$21),"") | N21: =IF(ISNUMBER(G21),VLOOKUP(VALUE(COUNTIF($E$12:$E$21,"NA015")),$T$2:$U$27,2),"") | O21: =IF(ISNUMBER(F21),IF(ABS(L21-F21)<1,"PASS","FAIL"),"") | P21: =IF(ISNUMBER(F21),IF((L21-F21)-(N21*M21)<0,"PASS","FAIL"),"") | Q21: =IF(ISNUMBER(F21),IF(G21>(L21+(M21*3)),"FAIL","PASS"),"") | R21: =IF(ISNUMBER(F21),IF(G21<(L21-(M21*3)),"FAIL","PASS"),"") | T21: 24 | U21: 1.8985
C22: FAM | E22: NA014 | I22: 10000 | J22: =LOG(I22) -> 4 | L22: =IF(ISNUMBER(F22),AVERAGE($F$22:$F$31),"") | M22: =IF(ISNUMBER(F22),STDEV($F$22:$F$31),"") | N22: =IF(ISNUMBER(G22),VLOOKUP(VALUE(COUNTIF($E$22:$E$31,"NA014")),$T$2:$U$27,2),"") | O22: =IF(ISNUMBER(F22),IF(ABS(L22-F22)<1,"PASS","FAIL"),"") | P22: =IF(ISNUMBER(F22),IF((L22-F22)-(N22*M22)<0,"PASS","FAIL"),"") | Q22: =IF(ISNUMBER(F22),IF(G22>(L22+(M22*3)),"FAIL","PASS"),"") | R22: =IF(ISNUMBER(F22),IF(G22<(L22-(M22*3)),"FAIL","PASS"),"") | T22: 25 | U22: 1.9011
C23: FAM | E23: NA014 | I23: 10000 | J23: =LOG(I23) -> 4 | L23: =IF(ISNUMBER(F23),AVERAGE($F$22:$F$31),"") | M23: =IF(ISNUMBER(F23),STDEV($F$22:$F$31),"") | N23: =IF(ISNUMBER(G23),VLOOKUP(VALUE(COUNTIF($E$22:$E$31,"NA014")),$T$2:$U$27,2),"") | O23: =IF(ISNUMBER(F23),IF(ABS(L23-F23)<1,"PASS","FAIL"),"") | P23: =IF(ISNUMBER(F23),IF((L23-F23)-(N23*M23)<0,"PASS","FAIL"),"") | Q23: =IF(ISNUMBER(F23),IF(G23>(L23+(M23*3)),"FAIL","PASS"),"") | R23: =IF(ISNUMBER(F23),IF(G23<(L23-(M23*3)),"FAIL","PASS"),"") | T23: 26 | U23: 1.9035
C24: FAM | E24: NA014 | I24: 10000 | J24: =LOG(I24) -> 4 | L24: =IF(ISNUMBER(F24),AVERAGE($F$22:$F$31),"") | M24: =IF(ISNUMBER(F24),STDEV($F$22:$F$31),"") | N24: =IF(ISNUMBER(G24),VLOOKUP(VALUE(COUNTIF($E$22:$E$31,"NA014")),$T$2:$U$27,2),"") | O24: =IF(ISNUMBER(F24),IF(ABS(L24-F24)<1,"PASS","FAIL"),"") | P24: =IF(ISNUMBER(F24),IF((L24-F24)-(N24*M24)<0,"PASS","FAIL"),"") | Q24: =IF(ISNUMBER(F24),IF(G24>(L24+(M24*3)),"FAIL","PASS"),"") | R24: =IF(ISNUMBER(F24),IF(G24<(L24-(M24*3)),"FAIL","PASS"),"") | T24: 27 | U24: 1.9057
C25: FAM | E25: NA014 | I25: 10000 | J25: =LOG(I25) -> 4 | L25: =IF(ISNUMBER(F25),AVERAGE($F$22:$F$31),"") | M25: =IF(ISNUMBER(F25),STDEV($F$22:$F$31),"") | N25: =IF(ISNUMBER(G25),VLOOKUP(VALUE(COUNTIF($E$22:$E$31,"NA014")),$T$2:$U$27,2),"") | O25: =IF(ISNUMBER(F25),IF(ABS(L25-F25)<1,"PASS","FAIL"),"") | P25: =IF(ISNUMBER(F25),IF((L25-F25)-(N25*M25)<0,"PASS","FAIL"),"") | Q25: =IF(ISNUMBER(F25),IF(G25>(L25+(M25*3)),"FAIL","PASS"),"") | R25: =IF(ISNUMBER(F25),IF(G25<(L25-(M25*3)),"FAIL","PASS"),"") | T25: 28 | U25: 1.9078
A26: NA014 | L26: =IF(ISNUMBER(F26),AVERAGE($F$22:$F$31),"") | M26: =IF(ISNUMBER(F26),STDEV($F$22:$F$31),"") | N26: =IF(ISNUMBER(G26),VLOOKUP(VALUE(COUNTIF($E$22:$E$31,"NA014")),$T$2:$U$27,2),"") | O26: =IF(ISNUMBER(F26),IF(ABS(L26-F26)<1,"PASS","FAIL"),"") | P26: =IF(ISNUMBER(F26),IF((L26-F26)-(N26*M26)<0,"PASS","FAIL"),"") | Q26: =IF(ISNUMBER(F26),IF(G26>(L26+(M26*3)),"FAIL","PASS"),"") | R26: =IF(ISNUMBER(F26),IF(G26<(L26-(M26*3)),"FAIL","PASS"),"") | T26: 29 | U26: 1.9096
A27: ONLY | L27: =IF(ISNUMBER(F27),AVERAGE($F$22:$F$31),"") | M27: =IF(ISNUMBER(F27),STDEV($F$22:$F$31),"") | N27: =IF(ISNUMBER(G27),VLOOKUP(VALUE(COUNTIF($E$22:$E$31,"NA014")),$T$2:$U$27,2),"") | O27: =IF(ISNUMBER(F27),IF(ABS(L27-F27)<1,"PASS","FAIL"),"") | P27: =IF(ISNUMBER(F27),IF((L27-F27)-(N27*M27)<0,"PASS","FAIL"),"") | Q27: =IF(ISNUMBER(F27),IF(G27>(L27+(M27*3)),"FAIL","PASS"),"") | R27: =IF(ISNUMBER(F27),IF(G27<(L27-(M27*3)),"FAIL","PASS"),"") | T27: 30 | U27: 1.9114
L28: =IF(ISNUMBER(F28),AVERAGE($F$22:$F$31),"") | M28: =IF(ISNUMBER(F28),STDEV($F$22:$F$31),"") | N28: =IF(ISNUMBER(G28),VLOOKUP(VALUE(COUNTIF($E$22:$E$31,"NA014")),$T$2:$U$27,2),"") | O28: =IF(ISNUMBER(F28),IF(ABS(L28-F28)<1,"PASS","FAIL"),"") | P28: =IF(ISNUMBER(F28),IF((L28-F28)-(N28*M28)<0,"PASS","FAIL"),"") | Q28: =IF(ISNUMBER(F28),IF(G28>(L28+(M28*3)),"FAIL","PASS"),"") | R28: =IF(ISNUMBER(F28),IF(G28<(L28-(M28*3)),"FAIL","PASS"),"")
L29: =IF(ISNUMBER(F29),AVERAGE($F$22:$F$31),"") | M29: =IF(ISNUMBER(F29),STDEV($F$22:$F$31),"") | N29: =IF(ISNUMBER(G29),VLOOKUP(VALUE(COUNTIF($E$22:$E$31,"NA014")),$T$2:$U$27,2),"") | O29: =IF(ISNUMBER(F29),IF(ABS(L29-F29)<1,"PASS","FAIL"),"") | P29: =IF(ISNUMBER(F29),IF((L29-F29)-(N29*M29)<0,"PASS","FAIL"),"") | Q29: =IF(ISNUMBER(F29),IF(G29>(L29+(M29*3)),"FAIL","PASS"),"") | R29: =IF(ISNUMBER(F29),IF(G29<(L29-(M29*3)),"FAIL","PASS"),"")
L30: =IF(ISNUMBER(F30),AVERAGE($F$22:$F$31),"") | M30: =IF(ISNUMBER(F30),STDEV($F$22:$F$31),"") | N30: =IF(ISNUMBER(G30),VLOOKUP(VALUE(COUNTIF($E$22:$E$31,"NA014")),$T$2:$U$27,2),"") | O30: =IF(ISNUMBER(F30),IF(ABS(L30-F30)<1,"PASS","FAIL"),"") | P30: =IF(ISNUMBER(F30),IF((L30-F30)-(N30*M30)<0,"PASS","FAIL"),"") | Q30: =IF(ISNUMBER(F30),IF(G30>(L30+(M30*3)),"FAIL","PASS"),"") | R30: =IF(ISNUMBER(F30),IF(G30<(L30-(M30*3)),"FAIL","PASS"),"")
L31: =IF(ISNUMBER(F31),AVERAGE($F$22:$F$31),"") | M31: =IF(ISNUMBER(F31),STDEV($F$22:$F$31),"") | N31: =IF(ISNUMBER(G31),VLOOKUP(VALUE(COUNTIF($E$22:$E$31,"NA014")),$T$2:$U$27,2),"") | O31: =IF(ISNUMBER(F31),IF(ABS(L31-F31)<1,"PASS","FAIL"),"") | P31: =IF(ISNUMBER(F31),IF((L31-F31)-(N31*M31)<0,"PASS","FAIL"),"") | Q31: =IF(ISNUMBER(F31),IF(G31>(L31+(M31*3)),"FAIL","PASS"),"") | R31: =IF(ISNUMBER(F31),IF(G31<(L31-(M31*3)),"FAIL","PASS"),"")
C32: FAM | E32: NA013 | I32: 1000 | J32: =LOG(I32) -> 3 | L32: =IF(ISNUMBER(F32),AVERAGE($F$32:$F$41),"") | M32: =IF(ISNUMBER(F32),STDEV($F$32:$F$41),"") | N32: =IF(ISNUMBER(G32),VLOOKUP(VALUE(COUNTIF($E$32:$E$41,"NA013")),$T$2:$U$27,2),"") | O32: =IF(ISNUMBER(F32),IF(ABS(L32-F32)<1,"PASS","FAIL"),"") | P32: =IF(ISNUMBER(F32),IF((L32-F32)-(N32*M32)<0,"PASS","FAIL"),"") | Q32: =IF(ISNUMBER(F32),IF(G32>(L32+(M32*3)),"FAIL","PASS"),"") | R32: =IF(ISNUMBER(F32),IF(G32<(L32-(M32*3)),"FAIL","PASS"),"")
C33: FAM | E33: NA013 | I33: 1000 | J33: =LOG(I33) -> 3 | L33: =IF(ISNUMBER(F33),AVERAGE($F$32:$F$41),"") | M33: =IF(ISNUMBER(F33),STDEV($F$32:$F$41),"") | N33: =IF(ISNUMBER(G33),VLOOKUP(VALUE(COUNTIF($E$32:$E$41,"NA013")),$T$2:$U$27,2),"") | O33: =IF(ISNUMBER(F33),IF(ABS(L33-F33)<1,"PASS","FAIL"),"") | P33: =IF(ISNUMBER(F33),IF((L33-F33)-(N33*M33)<0,"PASS","FAIL"),"") | Q33: =IF(ISNUMBER(F33),IF(G33>(L33+(M33*3)),"FAIL","PASS"),"") | R33: =IF(ISNUMBER(F33),IF(G33<(L33-(M33*3)),"FAIL","PASS"),"")
L34: =IF(ISNUMBER(F34),AVERAGE($F$32:$F$41),"") | M34: =IF(ISNUMBER(F34),STDEV($F$32:$F$41),"") | N34: =IF(ISNUMBER(G34),VLOOKUP(VALUE(COUNTIF($E$32:$E$41,"NA013")),$T$2:$U$27,2),"") | O34: =IF(ISNUMBER(F34),IF(ABS(L34-F34)<1,"PASS","FAIL"),"") | P34: =IF(ISNUMBER(F34),IF((L34-F34)-(N34*M34)<0,"PASS","FAIL"),"") | Q34: =IF(ISNUMBER(F34),IF(G34>(L34+(M34*3)),"FAIL","PASS"),"") | R34: =IF(ISNUMBER(F34),IF(G34<(L34-(M34*3)),"FAIL","PASS"),"")
L35: =IF(ISNUMBER(F35),AVERAGE($F$32:$F$41),"") | M35: =IF(ISNUMBER(F35),STDEV($F$32:$F$41),"") | N35: =IF(ISNUMBER(G35),VLOOKUP(VALUE(COUNTIF($E$32:$E$41,"NA013")),$T$2:$U$27,2),"") | O35: =IF(ISNUMBER(F35),IF(ABS(L35-F35)<1,"PASS","FAIL"),"") | P35: =IF(ISNUMBER(F35),IF((L35-F35)-(N35*M35)<0,"PASS","FAIL"),"") | Q35: =IF(ISNUMBER(F35),IF(G35>(L35+(M35*3)),"FAIL","PASS"),"") | R35: =IF(ISNUMBER(F35),IF(G35<(L35-(M35*3)),"FAIL","PASS"),"")
A36: NA013 | L36: =IF(ISNUMBER(F36),AVERAGE($F$32:$F$41),"") | M36: =IF(ISNUMBER(F36),STDEV($F$32:$F$41),"") | N36: =IF(ISNUMBER(G36),VLOOKUP(VALUE(COUNTIF($E$32:$E$41,"NA013")),$T$2:$U$27,2),"") | O36: =IF(ISNUMBER(F36),IF(ABS(L36-F36)<1,"PASS","FAIL"),"") | P36: =IF(ISNUMBER(F36),IF((L36-F36)-(N36*M36)<0,"PASS","FAIL"),"") | Q36: =IF(ISNUMBER(F36),IF(G36>(L36+(M36*3)),"FAIL","PASS"),"") | R36: =IF(ISNUMBER(F36),IF(G36<(L36-(M36*3)),"FAIL","PASS"),"")
A37: ONLY | L37: =IF(ISNUMBER(F37),AVERAGE($F$32:$F$41),"") | M37: =IF(ISNUMBER(F37),STDEV($F$32:$F$41),"") | N37: =IF(ISNUMBER(G37),VLOOKUP(VALUE(COUNTIF($E$32:$E$41,"NA013")),$T$2:$U$27,2),"") | O37: =IF(ISNUMBER(F37),IF(ABS(L37-F37)<1,"PASS","FAIL"),"") | P37: =IF(ISNUMBER(F37),IF((L37-F37)-(N37*M37)<0,"PASS","FAIL"),"") | Q37: =IF(ISNUMBER(F37),IF(G37>(L37+(M37*3)),"FAIL","PASS"),"") | R37: =IF(ISNUMBER(F37),IF(G37<(L37-(M37*3)),"FAIL","PASS"),"")
L38: =IF(ISNUMBER(F38),AVERAGE($F$32:$F$41),"") | M38: =IF(ISNUMBER(F38),STDEV($F$32:$F$41),"") | N38: =IF(ISNUMBER(G38),VLOOKUP(VALUE(COUNTIF($E$32:$E$41,"NA013")),$T$2:$U$27,2),"") | O38: =IF(ISNUMBER(F38),IF(ABS(L38-F38)<1,"PASS","FAIL"),"") | P38: =IF(ISNUMBER(F38),IF((L38-F38)-(N38*M38)<0,"PASS","FAIL"),"") | Q38: =IF(ISNUMBER(F38),IF(G38>(L38+(M38*3)),"FAIL","PASS"),"") | R38: =IF(ISNUMBER(F38),IF(G38<(L38-(M38*3)),"FAIL","PASS"),"")
L39: =IF(ISNUMBER(F39),AVERAGE($F$32:$F$41),"") | M39: =IF(ISNUMBER(F39),STDEV($F$32:$F$41),"") | N39: =IF(ISNUMBER(G39),VLOOKUP(VALUE(COUNTIF($E$32:$E$41,"NA013")),$T$2:$U$27,2),"") | O39: =IF(ISNUMBER(F39),IF(ABS(L39-F39)<1,"PASS","FAIL"),"") | P39: =IF(ISNUMBER(F39),IF((L39-F39)-(N39*M39)<0,"PASS","FAIL"),"") | Q39: =IF(ISNUMBER(F39),IF(G39>(L39+(M39*3)),"FAIL","PASS"),"") | R39: =IF(ISNUMBER(F39),IF(G39<(L39-(M39*3)),"FAIL","PASS"),"")
L40: =IF(ISNUMBER(F40),AVERAGE($F$32:$F$41),"") | M40: =IF(ISNUMBER(F40),STDEV($F$32:$F$41),"") | N40: =IF(ISNUMBER(G40),VLOOKUP(VALUE(COUNTIF($E$32:$E$41,"NA013")),$T$2:$U$27,2),"") | O40: =IF(ISNUMBER(F40),IF(ABS(L40-F40)<1,"PASS","FAIL"),"") | P40: =IF(ISNUMBER(F40),IF((L40-F40)-(N40*M40)<0,"PASS","FAIL"),"") | Q40: =IF(ISNUMBER(F40),IF(G40>(L40+(M40*3)),"FAIL","PASS"),"") | R40: =IF(ISNUMBER(F40),IF(G40<(L40-(M40*3)),"FAIL","PASS"),"")
...

Sheet NTC
A1: Well Position | B1: Sample Name | C1: Target Name | D1: Reporter | E1: Ct Machine | F1: Ct Mean Machine | G1: Ct Std. Dev Machine | H1: Ct Data File Name | I1: Test 5
I2: =IF(ISNUMBER(E2),IF(E2>36,"PASS","FAIL"),"")
I3: =IF(ISNUMBER(E3),IF(E3>36,"PASS","FAIL"),"")
I4: =IF(ISNUMBER(E4),IF(E4>36,"PASS","FAIL"),"")
I5: =IF(ISNUMBER(E5),IF(E5>36,"PASS","FAIL"),"")
I6: =IF(ISNUMBER(E6),IF(E6>36,"PASS","FAIL"),"")
I7: =IF(ISNUMBER(E7),IF(E7>36,"PASS","FAIL"),"")
I8: =IF(ISNUMBER(E8),IF(E8>36,"PASS","FAIL"),"")
I9: =IF(ISNUMBER(E9),IF(E9>36,"PASS","FAIL"),"")
I10: =IF(ISNUMBER(E10),IF(E10>36,"PASS","FAIL"),"")
I11: =IF(ISNUMBER(E11),IF(E11>36,"PASS","FAIL"),"")
I12: =IF(ISNUMBER(E12),IF(E12>36,"PASS","FAIL"),"")
I13: =IF(ISNUMBER(E13),IF(E13>36,"PASS","FAIL"),"")
... I100: =IF(ISNUMBER(E100),IF(E100>36,"PASS","FAIL"),"")

Sheet Negative Controls
A1: Well Position | B1: Sample Name | C1: Target Name | D1: Reporter | E1: Ct Machine | F1: Ct Mean Machine | G1: Ct Std. Dev Machine | H1: Ct Data File Name | I1: Test 6
I2: =IF(ISNUMBER(E2), IF(E2>'Outlier Check'!$L$42,"PASS","FAIL"),"")
I3: =IF(ISNUMBER(E3), IF(E3>'Outlier Check'!$L$42,"PASS","FAIL"),"")
I4: =IF(ISNUMBER(E4), IF(E4>'Outlier Check'!$L$42,"PASS","FAIL"),"")
I5: =IF(ISNUMBER(E5), IF(E5>'Outlier Check'!$L$42,"PASS","FAIL"),"")
I6: =IF(ISNUMBER(E6), IF(E6>'Outlier Check'!$L$42,"PASS","FAIL"),"")
I7: =IF(ISNUMBER(E7), IF(E7>'Outlier Check'!$L$42,"PASS","FAIL"),"")
I8: =IF(ISNUMBER(E8), IF(E8>'Outlier Check'!$L$42,"PASS","FAIL"),"")
I9: =IF(ISNUMBER(E9), IF(E9>'Outlier Check'!$L$42,"PASS","FAIL"),"")
I10: =IF(ISNUMBER(E10), IF(E10>'Outlier Check'!$L$42,"PASS","FAIL"),"")
I11: =IF(ISNUMBER(E11), IF(E11>'Outlier Check'!$L$42,"PASS","FAIL"),"")
I12: =IF(ISNUMBER(E12), IF(E12>'Outlier Check'!$L$42,"PASS","FAIL"),"")
I13: =IF(ISNUMBER(E13), IF(E13>'Outlier Check'!$L$42,"PASS","FAIL"),"")
... I100: =IF(ISNUMBER(E100), IF(E100>'Outlier Check'!$L$42,"PASS","FAIL"),"")

Sheet Sample Metadata
A1: Project | B1: Date Sample Taken | C1: Time Sample Taken | D1: Sample ID | E1: DNA ID | F1: Volume Filtered | G1: Date Extracted | H1: Volume Eluted | I1: Volume Template
I2: 5
I3: 5
I4: 5
I5: 5
I6: 5
I7: 5
I8: 5
I9: 5
I10: 5
I11: 5
I12: 5
I13: 5
... I43: 5

Sheet qPCR Run Entry
A1: RUN 1 | L1: RUN 2 | W1: RUN 3
A3: Sample ID | B3: Well Position | C3: Sample Name | D3: Dilution Factor | E3: Target Name | F3: Reporter | G3: Ct Machine | H3: Ct Mean Machine | I3: Ct Std. Dev Machine | J3: Ct Data File Name | L3: Sample ID | M3: Well Position | N3: Sample Name | O3: Dilution | P3: Target Name | Q3: Reporter | R3: Ct Machine | S3: Ct Mean Machine | T3: Ct Std. Dev Machine | U3: Ct Data File Name | W3: Sample ID | X3: Well Position | Y3: Sample Name | Z3: Dilution | AA3: Target Name | AB3: Reporter | AC3: Ct Machine | AD3: Ct Mean Machine | AE3: Ct Std. Dev Machine | AF3: Ct Data File Name
A4: ='Sample Metadata'!D2 -> 0 | L4: =A4 -> 0 | W4: =L4 -> 0
A6: ='Sample Metadata'!D3 -> 0 | L6: =A6 -> 0 | W6: =L6 -> 0
A8: ='Sample Metadata'!D4 -> 0 | L8: =A8 -> 0 | W8: =L8 -> 0
A10: ='Sample Metadata'!D5 -> 0 | L10: =A10 -> 0 | W10: =L10 -> 0
A12: ='Sample Metadata'!D6 -> 0 | L12: =A12 -> 0 | W12: =L12 -> 0
A14: ='Sample Metadata'!D7 -> 0 | L14: =A14 -> 0 | W14: =L14 -> 0
A16: ='Sample Metadata'!D8 -> 0 | L16: =A16 -> 0 | W16: =L16 -> 0
A18: ='Sample Metadata'!D9 -> 0 | L18: =A18 -> 0 | W18: =L18 -> 0
A20: ='Sample Metadata'!D10 -> 0 | L20: =A20 -> 0 | W20: =L20 -> 0
A22: ='Sample Metadata'!D11 -> 0 | L22: =A22 -> 0 | W22: =L22 -> 0
A24: ='Sample Metadata'!D12 -> 0 | L24: =A24 -> 0 | W24: =L24 -> 0
A26: ='Sample Metadata'!D13 -> 0 | L26: =A26 -> 0 | W26: =L26 -> 0
A28: ='Sample Metadata'!D14 -> 0 | L28: =A28 -> 0 | W28: =L28 -> 0
A30: ='Sample Metadata'!D15 -> 0 | L30: =A30 -> 0 | W30: =L30 -> 0
A32: ='Sample Metadata'!D16 -> 0 | L32: =A32 -> 0 | W32: =L32 -> 0
A34: ='Sample Metadata'!D17 -> 0 | L34: =A34 -> 0 | W34: =L34 -> 0
A36: ='Sample Metadata'!D18 -> 0 | L36: =A36 -> 0 | W36: =L36 -> 0
A38: ='Sample Metadata'!D19 -> 0 | L38: =A38 -> 0 | W38: =L38 -> 0
A40: ='Sample Metadata'!D20 -> 0 | L40: =A40 -> 0 | W40: =L40 -> 0
A42: ='Sample Metadata'!D21 -> 0 | L42: =A42 -> 0 | W42: =L42 -> 0
A44: ='Sample Metadata'!D22 -> 0 | L44: =A44 -> 0 | W44: =L44 -> 0
A46: ='Sample Metadata'!D23 -> 0 | L46: =A46 -> 0 | W46: =L46 -> 0
A48: ='Sample Metadata'!D24 -> 0 | L48: =A48 -> 0 | W48: =L48 -> 0
A50: ='Sample Metadata'!D25 -> 0 | L50: =A50 -> 0 | W50: =L50 -> 0
A52: ='Sample Metadata'!D26 -> 0 | L52: =A52 -> 0 | W52: =L52 -> 0
A54: ='Sample Metadata'!D27 -> 0 | L54: =A54 -> 0 | W54: =L54 -> 0
A56: ='Sample Metadata'!D28 -> 0 | L56: =A56 -> 0 | W56: =L56 -> 0
A58: ='Sample Metadata'!D29 -> 0 | L58: =A58 -> 0 | W58: =L58 -> 0
A60: ='Sample Metadata'!D30 -> 0 | L60: =A60 -> 0 | W60: =L60 -> 0
A62: ='Sample Metadata'!D31 -> 0 | L62: =A62 -> 0 | W62: =L62 -> 0
A64: ='Sample Metadata'!D32 -> 0 | L64: =A64 -> 0 | W64: =L64 -> 0
A66: ='Sample Metadata'!D33 -> 0 | L66: =A66 -> 0 | W66: =L66 -> 0
A68: ='Sample Metadata'!D34 -> 0 | L68: =A68 -> 0 | W68: =L68 -> 0
A70: ='Sample Metadata'!D35 -> 0 | L70: =A70 -> 0 | W70: =L70 -> 0
A72: ='Sample Metadata'!D36 -> 0 | L72: =A72 -> 0 | W72: =L72 -> 0
A74: ='Sample Metadata'!D37 -> 0 | L74: =A74 -> 0 | W74: =L74 -> 0
A76: ='Sample Metadata'!D38 -> 0 | L76: =A76 -> 0 | W76: =L76 -> 0
A78: ='Sample Metadata'!D39 -> 0 | L78: =A78 -> 0 | W78: =L78 -> 0
...

Sheet IAC
A1: RUN 1 | O1: RUN 2 | AC1: RUN 3
A3: Sample ID | B3: Well Position | C3: Sample Name | D3: Dilution Factor | E3: Target Name | F3: Reporter | G3: Ct Machine | H3: Ct Mean Machine | I3: Ct Std. Dev Machine | J3: Ct Data File Name | K3: Ct Mean (NTC of Run) | L3: Ct - Ct Mean (NTC of Run) | M3: Test 7 | O3: Sample ID | P3: Well Position | Q3: Sample Name | R3: Dilution | S3: Target Name | T3: Reporter | U3: Ct Machine | V3: Ct Mean Machine | W3: Ct Std. Dev Machine | X3: Ct Data File Name | Y3: Ct Mean (NTC of Run) | Z3: Ct - Ct Mean (NTC of Run) | AA3: Test 7 | AC3: Sample ID | AD3: Well Position | AE3: Sample Name | AF3: Dilution | AG3: Target Name | AH3: Reporter | AI3: Ct Machine | AJ3: Ct Mean Machine | AK3: Ct Std. Dev Machine | AL3: Ct Data File Name | AM3: Ct Mean (NTC of Run) | AN3: Ct - Ct Mean (NTC of Run) | AO3: Test 7
A4: ='Sample Metadata'!D2 -> 0 | B4: =IF('qPCR Run Entry'!B4="","",'qPCR Run Entry'!B4) | C4: =IF('qPCR Run Entry'!C4="","",'qPCR Run Entry'!C4) | D4: =IF('qPCR Run Entry'!D4="","",'qPCR Run Entry'!D4) | E4: IAC | F4: CALFL-ORNG | J4: =IF('qPCR Run Entry'!J4="","",'qPCR Run Entry'!J4) | L4: =G4-K4 -> 0 | M4: =IF(ISNUMBER(K4),IF(ABS(L4)>1.5, "FAIL", "Pass"),"") | O4: =A4 -> 0 | P4: =IF('qPCR Run Entry'!M4="","",'qPCR Run Entry'!M4) | Q4: =IF('qPCR Run Entry'!N4="","",'qPCR Run Entry'!N4) | R4: =IF('qPCR Run Entry'!O4="","",'qPCR Run Entry'!O4) | S4: IAC | T4: CALFL-ORNG | X4: =IF('qPCR Run Entry'!U4="","",'qPCR Run Entry'!U4) | Z4: =U4-Y4 -> 0 | AA4: =IF(ISNUMBER(Y4),IF(ABS(Z4)>1.5, "FAIL", "Pass"),"") | AC4: =O4 -> 0 | AD4: =IF('qPCR Run Entry'!X4="","",'qPCR Run Entry'!X4) | AE4: =IF('qPCR Run Entry'!Y4="","",'qPCR Run Entry'!Y4) | AF4: =IF('qPCR Run Entry'!Z4="","",'qPCR Run Entry'!Z4) | AG4: IAC | AH4: CALFL-ORNG | AL4: =IF('qPCR Run Entry'!AF4="","",'qPCR Run Entry'!AF4) | AN4: =AI4-AM4 -> 0 | AO4: =IF(ISNUMBER(AM4),IF(ABS(AN4)>1.5, "FAIL", "Pass"),"")
B5: =IF('qPCR Run Entry'!B5="","",'qPCR Run Entry'!B5) | C5: =IF('qPCR Run Entry'!C5="","",'qPCR Run Entry'!C5) | E5: IAC | F5: CALFL-ORNG | J5: =IF('qPCR Run Entry'!J5="","",'qPCR Run Entry'!J5) | L5: =G5-K5 -> 0 | M5: =IF(ISNUMBER(K5),IF(ABS(L5)>1.5, "FAIL", "Pass"),"") | P5: =IF('qPCR Run Entry'!M5="","",'qPCR Run Entry'!M5) | Q5: =IF('qPCR Run Entry'!N5="","",'qPCR Run Entry'!N5) | R5: =IF('qPCR Run Entry'!O5="","",'qPCR Run Entry'!O5) | S5: IAC | T5: CALFL-ORNG | X5: =IF('qPCR Run Entry'!U5="","",'qPCR Run Entry'!U5) | Z5: =U5-Y5 -> 0 | AA5: =IF(ISNUMBER(Y5),IF(ABS(Z5)>1.5, "FAIL", "Pass"),"") | AD5: =IF('qPCR Run Entry'!X5="","",'qPCR Run Entry'!X5) | AE5: =IF('qPCR Run Entry'!Y5="","",'qPCR Run Entry'!Y5) | AF5: =IF('qPCR Run Entry'!Z5="","",'qPCR Run Entry'!Z5) | AG5: IAC | AH5: CALFL-ORNG | AL5: =IF('qPCR Run Entry'!AF5="","",'qPCR Run Entry'!AF5) | AN5: =AI5-AM5 -> 0 | AO5: =IF(ISNUMBER(AM5),IF(ABS(AN5)>1.5, "FAIL", "Pass"),"")
A6: ='Sample Metadata'!D3 -> 0 | B6: =IF('qPCR Run Entry'!B6="","",'qPCR Run Entry'!B6) | C6: =IF('qPCR Run Entry'!C6="","",'qPCR Run Entry'!C6) | D6: =IF('qPCR Run Entry'!D6="","",'qPCR Run Entry'!D6) | E6: IAC | F6: CALFL-ORNG | J6: =IF('qPCR Run Entry'!J6="","",'qPCR Run Entry'!J6) | L6: =G6-K6 -> 0 | M6: =IF(ISNUMBER(K6),IF(ABS(L6)>1.5, "FAIL", "Pass"),"") | O6: =A6 -> 0 | P6: =IF('qPCR Run Entry'!M6="","",'qPCR Run Entry'!M6) | Q6: =IF('qPCR Run Entry'!N6="","",'qPCR Run Entry'!N6) | R6: =IF('qPCR Run Entry'!O6="","",'qPCR Run Entry'!O6) | S6: IAC | T6: CALFL-ORNG | X6: =IF('qPCR Run Entry'!U6="","",'qPCR Run Entry'!U6) | Z6: =U6-Y6 -> 0 | AA6: =IF(ISNUMBER(Y6),IF(ABS(Z6)>1.5, "FAIL", "Pass"),"") | AC6: =O6 -> 0 | AD6: =IF('qPCR Run Entry'!X6="","",'qPCR Run Entry'!X6) | AE6: =IF('qPCR Run Entry'!Y6="","",'qPCR Run Entry'!Y6) | AF6: =IF('qPCR Run Entry'!Z6="","",'qPCR Run Entry'!Z6) | AG6: IAC | AH6: CALFL-ORNG | AL6: =IF('qPCR Run Entry'!AF6="","",'qPCR Run Entry'!AF6) | AN6: =AI6-AM6 -> 0 | AO6: =IF(ISNUMBER(AM6),IF(ABS(AN6)>1.5, "FAIL", "Pass"),"")
B7: =IF('qPCR Run Entry'!B7="","",'qPCR Run Entry'!B7) | C7: =IF('qPCR Run Entry'!C7="","",'qPCR Run Entry'!C7) | E7: IAC | F7: CALFL-ORNG | J7: =IF('qPCR Run Entry'!J7="","",'qPCR Run Entry'!J7) | L7: =G7-K7 -> 0 | M7: =IF(ISNUMBER(K7),IF(ABS(L7)>1.5, "FAIL", "Pass"),"") | P7: =IF('qPCR Run Entry'!M7="","",'qPCR Run Entry'!M7) | Q7: =IF('qPCR Run Entry'!N7="","",'qPCR Run Entry'!N7) | R7: =IF('qPCR Run Entry'!O7="","",'qPCR Run Entry'!O7) | S7: IAC | T7: CALFL-ORNG | X7: =IF('qPCR Run Entry'!U7="","",'qPCR Run Entry'!U7) | Z7: =U7-Y7 -> 0 | AA7: =IF(ISNUMBER(Y7),IF(ABS(Z7)>1.5, "FAIL", "Pass"),"") | AD7: =IF('qPCR Run Entry'!X7="","",'qPCR Run Entry'!X7) | AE7: =IF('qPCR Run Entry'!Y7="","",'qPCR Run Entry'!Y7) | AF7: =IF('qPCR Run Entry'!Z7="","",'qPCR Run Entry'!Z7) | AG7: IAC | AH7: CALFL-ORNG | AL7: =IF('qPCR Run Entry'!AF7="","",'qPCR Run Entry'!AF7) | AN7: =AI7-AM7 -> 0 | AO7: =IF(ISNUMBER(AM7),IF(ABS(AN7)>1.5, "FAIL", "Pass"),"")
A8: ='Sample Metadata'!D4 -> 0 | B8: =IF('qPCR Run Entry'!B8="","",'qPCR Run Entry'!B8) | C8: =IF('qPCR Run Entry'!C8="","",'qPCR Run Entry'!C8) | D8: =IF('qPCR Run Entry'!D8="","",'qPCR Run Entry'!D8) | E8: IAC | F8: CALFL-ORNG | J8: =IF('qPCR Run Entry'!J8="","",'qPCR Run Entry'!J8) | L8: =G8-K8 -> 0 | M8: =IF(ISNUMBER(K8),IF(ABS(L8)>1.5, "FAIL", "Pass"),"") | O8: =A8 -> 0 | P8: =IF('qPCR Run Entry'!M8="","",'qPCR Run Entry'!M8) | Q8: =IF('qPCR Run Entry'!N8="","",'qPCR Run Entry'!N8) | R8: =IF('qPCR Run Entry'!O8="","",'qPCR Run Entry'!O8) | S8: IAC | T8: CALFL-ORNG | X8: =IF('qPCR Run Entry'!U8="","",'qPCR Run Entry'!U8) | Z8: =U8-Y8 -> 0 | AA8: =IF(ISNUMBER(Y8),IF(ABS(Z8)>1.5, "FAIL", "Pass"),"") | AC8: =O8 -> 0 | AD8: =IF('qPCR Run Entry'!X8="","",'qPCR Run Entry'!X8) | AE8: =IF('qPCR Run Entry'!Y8="","",'qPCR Run Entry'!Y8) | AF8: =IF('qPCR Run Entry'!Z8="","",'qPCR Run Entry'!Z8) | AG8: IAC | AH8: CALFL-ORNG | AL8: =IF('qPCR Run Entry'!AF8="","",'qPCR Run Entry'!AF8) | AN8: =AI8-AM8 -> 0 | AO8: =IF(ISNUMBER(AM8),IF(ABS(AN8)>1.5, "FAIL", "Pass"),"")
B9: =IF('qPCR Run Entry'!B9="","",'qPCR Run Entry'!B9) | C9: =IF('qPCR Run Entry'!C9="","",'qPCR Run Entry'!C9) | E9: IAC | F9: CALFL-ORNG | J9: =IF('qPCR Run Entry'!J9="","",'qPCR Run Entry'!J9) | L9: =G9-K9 -> 0 | M9: =IF(ISNUMBER(K9),IF(ABS(L9)>1.5, "FAIL", "Pass"),"") | P9: =IF('qPCR Run Entry'!M9="","",'qPCR Run Entry'!M9) | Q9: =IF('qPCR Run Entry'!N9="","",'qPCR Run Entry'!N9) | R9: =IF('qPCR Run Entry'!O9="","",'qPCR Run Entry'!O9) | S9: IAC | T9: CALFL-ORNG | X9: =IF('qPCR Run Entry'!U9="","",'qPCR Run Entry'!U9) | Z9: =U9-Y9 -> 0 | AA9: =IF(ISNUMBER(Y9),IF(ABS(Z9)>1.5, "FAIL", "Pass"),"") | AD9: =IF('qPCR Run Entry'!X9="","",'qPCR Run Entry'!X9) | AE9: =IF('qPCR Run Entry'!Y9="","",'qPCR Run Entry'!Y9) | AF9: =IF('qPCR Run Entry'!Z9="","",'qPCR Run Entry'!Z9) | AG9: IAC | AH9: CALFL-ORNG | AL9: =IF('qPCR Run Entry'!AF9="","",'qPCR Run Entry'!AF9) | AN9: =AI9-AM9 -> 0 | AO9: =IF(ISNUMBER(AM9),IF(ABS(AN9)>1.5, "FAIL", "Pass"),"")
A10: ='Sample Metadata'!D5 -> 0 | B10: =IF('qPCR Run Entry'!B10="","",'qPCR Run Entry'!B10) | C10: =IF('qPCR Run Entry'!C10="","",'qPCR Run Entry'!C10) | D10: =IF('qPCR Run Entry'!D10="","",'qPCR Run Entry'!D10) | E10: IAC | F10: CALFL-ORNG | J10: =IF('qPCR Run Entry'!J10="","",'qPCR Run Entry'!J10) | L10: =G10-K10 -> 0 | M10: =IF(ISNUMBER(K10),IF(ABS(L10)>1.5, "FAIL", "Pass"),"") | O10: =A10 -> 0 | P10: =IF('qPCR Run Entry'!M10="","",'qPCR Run Entry'!M10) | Q10: =IF('qPCR Run Entry'!N10="","",'qPCR Run Entry'!N10) | R10: =IF('qPCR Run Entry'!O10="","",'qPCR Run Entry'!O10) | S10: IAC | T10: CALFL-ORNG | X10: =IF('qPCR Run Entry'!U10="","",'qPCR Run Entry'!U10) | Z10: =U10-Y10 -> 0 | AA10: =IF(ISNUMBER(Y10),IF(ABS(Z10)>1.5, "FAIL", "Pass"),"") | AC10: =O10 -> 0 | AD10: =IF('qPCR Run Entry'!X10="","",'qPCR Run Entry'!X10) | AE10: =IF('qPCR Run Entry'!Y10="","",'qPCR Run Entry'!Y10) | AF10: =IF('qPCR Run Entry'!Z10="","",'qPCR Run Entry'!Z10) | AG10: IAC | AH10: CALFL-ORNG | AL10: =IF('qPCR Run Entry'!AF10="","",'qPCR Run Entry'!AF10) | AN10: =AI10-AM10 -> 0 | AO10: =IF(ISNUMBER(AM10),IF(ABS(AN10)>1.5, "FAIL", "Pass"),"")
B11: =IF('qPCR Run Entry'!B11="","",'qPCR Run Entry'!B11) | C11: =IF('qPCR Run Entry'!C11="","",'qPCR Run Entry'!C11) | E11: IAC | F11: CALFL-ORNG | J11: =IF('qPCR Run Entry'!J11="","",'qPCR Run Entry'!J11) | L11: =G11-K11 -> 0 | M11: =IF(ISNUMBER(K11),IF(ABS(L11)>1.5, "FAIL", "Pass"),"") | P11: =IF('qPCR Run Entry'!M11="","",'qPCR Run Entry'!M11) | Q11: =IF('qPCR Run Entry'!N11="","",'qPCR Run Entry'!N11) | R11: =IF('qPCR Run Entry'!O11="","",'qPCR Run Entry'!O11) | S11: IAC | T11: CALFL-ORNG | X11: =IF('qPCR Run Entry'!U11="","",'qPCR Run Entry'!U11) | Z11: =U11-Y11 -> 0 | AA11: =IF(ISNUMBER(Y11),IF(ABS(Z11)>1.5, "FAIL", "Pass"),"") | AD11: =IF('qPCR Run Entry'!X11="","",'qPCR Run Entry'!X11) | AE11: =IF('qPCR Run Entry'!Y11="","",'qPCR Run Entry'!Y11) | AF11: =IF('qPCR Run Entry'!Z11="","",'qPCR Run Entry'!Z11) | AG11: IAC | AH11: CALFL-ORNG | AL11: =IF('qPCR Run Entry'!AF11="","",'qPCR Run Entry'!AF11) | AN11: =AI11-AM11 -> 0 | AO11: =IF(ISNUMBER(AM11),IF(ABS(AN11)>1.5, "FAIL", "Pass"),"")
A12: ='Sample Metadata'!D6 -> 0 | B12: =IF('qPCR Run Entry'!B12="","",'qPCR Run Entry'!B12) | C12: =IF('qPCR Run Entry'!C12="","",'qPCR Run Entry'!C12) | D12: =IF('qPCR Run Entry'!D12="","",'qPCR Run Entry'!D12) | E12: IAC | F12: CALFL-ORNG | J12: =IF('qPCR Run Entry'!J12="","",'qPCR Run Entry'!J12) | L12: =G12-K12 -> 0 | M12: =IF(ISNUMBER(K12),IF(ABS(L12)>1.5, "FAIL", "Pass"),"") | O12: =A12 -> 0 | P12: =IF('qPCR Run Entry'!M12="","",'qPCR Run Entry'!M12) | Q12: =IF('qPCR Run Entry'!N12="","",'qPCR Run Entry'!N12) | R12: =IF('qPCR Run Entry'!O12="","",'qPCR Run Entry'!O12) | S12: IAC | T12: CALFL-ORNG | X12: =IF('qPCR Run Entry'!U12="","",'qPCR Run Entry'!U12) | Z12: =U12-Y12 -> 0 | AA12: =IF(ISNUMBER(Y12),IF(ABS(Z12)>1.5, "FAIL", "Pass"),"") | AC12: =O12 -> 0 | AD12: =IF('qPCR Run Entry'!X12="","",'qPCR Run Entry'!X12) | AE12: =IF('qPCR Run Entry'!Y12="","",'qPCR Run Entry'!Y12) | AF12: =IF('qPCR Run Entry'!Z12="","",'qPCR Run Entry'!Z12) | AG12: IAC | AH12: CALFL-ORNG | AL12: =IF('qPCR Run Entry'!AF12="","",'qPCR Run Entry'!AF12) | AN12: =AI12-AM12 -> 0 | AO12: =IF(ISNUMBER(AM12),IF(ABS(AN12)>1.5, "FAIL", "Pass"),"")
B13: =IF('qPCR Run Entry'!B13="","",'qPCR Run Entry'!B13) | C13: =IF('qPCR Run Entry'!C13="","",'qPCR Run Entry'!C13) | E13: IAC | F13: CALFL-ORNG | J13: =IF('qPCR Run Entry'!J13="","",'qPCR Run Entry'!J13) | L13: =G13-K13 -> 0 | M13: =IF(ISNUMBER(K13),IF(ABS(L13)>1.5, "FAIL", "Pass"),"") | P13: =IF('qPCR Run Entry'!M13="","",'qPCR Run Entry'!M13) | Q13: =IF('qPCR Run Entry'!N13="","",'qPCR Run Entry'!N13) | R13: =IF('qPCR Run Entry'!O13="","",'qPCR Run Entry'!O13) | S13: IAC | T13: CALFL-ORNG | X13: =IF('qPCR Run Entry'!U13="","",'qPCR Run Entry'!U13) | Z13: =U13-Y13 -> 0 | AA13: =IF(ISNUMBER(Y13),IF(ABS(Z13)>1.5, "FAIL", "Pass"),"") | AD13: =IF('qPCR Run Entry'!X13="","",'qPCR Run Entry'!X13) | AE13: =IF('qPCR Run Entry'!Y13="","",'qPCR Run Entry'!Y13) | AF13: =IF('qPCR Run Entry'!Z13="","",'qPCR Run Entry'!Z13) | AG13: IAC | AH13: CALFL-ORNG | AL13: =IF('qPCR Run Entry'!AF13="","",'qPCR Run Entry'!AF13) | AN13: =AI13-AM13 -> 0 | AO13: =IF(ISNUMBER(AM13),IF(ABS(AN13)>1.5, "FAIL", "Pass"),"")
A14: ='Sample Metadata'!D7 -> 0 | B14: =IF('qPCR Run Entry'!B14="","",'qPCR Run Entry'!B14) | C14: =IF('qPCR Run Entry'!C14="","",'qPCR Run Entry'!C14) | D14: =IF('qPCR Run Entry'!D14="","",'qPCR Run Entry'!D14) | E14: IAC | F14: CALFL-ORNG | J14: =IF('qPCR Run Entry'!J14="","",'qPCR Run Entry'!J14) | L14: =G14-K14 -> 0 | M14: =IF(ISNUMBER(K14),IF(ABS(L14)>1.5, "FAIL", "Pass"),"") | O14: =A14 -> 0 | P14: =IF('qPCR Run Entry'!M14="","",'qPCR Run Entry'!M14) | Q14: =IF('qPCR Run Entry'!N14="","",'qPCR Run Entry'!N14) | R14: =IF('qPCR Run Entry'!O14="","",'qPCR Run Entry'!O14) | S14: IAC | T14: CALFL-ORNG | X14: =IF('qPCR Run Entry'!U14="","",'qPCR Run Entry'!U14) | Z14: =U14-Y14 -> 0 | AA14: =IF(ISNUMBER(Y14),IF(ABS(Z14)>1.5, "FAIL", "Pass"),"") | AC14: =O14 -> 0 | AD14: =IF('qPCR Run Entry'!X14="","",'qPCR Run Entry'!X14) | AE14: =IF('qPCR Run Entry'!Y14="","",'qPCR Run Entry'!Y14) | AF14: =IF('qPCR Run Entry'!Z14="","",'qPCR Run Entry'!Z14) | AG14: IAC | AH14: CALFL-ORNG | AL14: =IF('qPCR Run Entry'!AF14="","",'qPCR Run Entry'!AF14) | AN14: =AI14-AM14 -> 0 | AO14: =IF(ISNUMBER(AM14),IF(ABS(AN14)>1.5, "FAIL", "Pass"),"")
B15: =IF('qPCR Run Entry'!B15="","",'qPCR Run Entry'!B15) | C15: =IF('qPCR Run Entry'!C15="","",'qPCR Run Entry'!C15) | E15: IAC | F15: CALFL-ORNG | J15: =IF('qPCR Run Entry'!J15="","",'qPCR Run Entry'!J15) | L15: =G15-K15 -> 0 | M15: =IF(ISNUMBER(K15),IF(ABS(L15)>1.5, "FAIL", "Pass"),"") | P15: =IF('qPCR Run Entry'!M15="","",'qPCR Run Entry'!M15) | Q15: =IF('qPCR Run Entry'!N15="","",'qPCR Run Entry'!N15) | R15: =IF('qPCR Run Entry'!O15="","",'qPCR Run Entry'!O15) | S15: IAC | T15: CALFL-ORNG | X15: =IF('qPCR Run Entry'!U15="","",'qPCR Run Entry'!U15) | Z15: =U15-Y15 -> 0 | AA15: =IF(ISNUMBER(Y15),IF(ABS(Z15)>1.5, "FAIL", "Pass"),"") | AD15: =IF('qPCR Run Entry'!X15="","",'qPCR Run Entry'!X15) | AE15: =IF('qPCR Run Entry'!Y15="","",'qPCR Run Entry'!Y15) | AF15: =IF('qPCR Run Entry'!Z15="","",'qPCR Run Entry'!Z15) | AG15: IAC | AH15: CALFL-ORNG | AL15: =IF('qPCR Run Entry'!AF15="","",'qPCR Run Entry'!AF15) | AN15: =AI15-AM15 -> 0 | AO15: =IF(ISNUMBER(AM15),IF(ABS(AN15)>1.5, "FAIL", "Pass"),"")
A16: ='Sample Metadata'!D8 -> 0 | B16: =IF('qPCR Run Entry'!B16="","",'qPCR Run Entry'!B16) | C16: =IF('qPCR Run Entry'!C16="","",'qPCR Run Entry'!C16) | D16: =IF('qPCR Run Entry'!D16="","",'qPCR Run Entry'!D16) | E16: IAC | F16: CALFL-ORNG | J16: =IF('qPCR Run Entry'!J16="","",'qPCR Run Entry'!J16) | L16: =G16-K16 -> 0 | M16: =IF(ISNUMBER(K16),IF(ABS(L16)>1.5, "FAIL", "Pass"),"") | O16: =A16 -> 0 | P16: =IF('qPCR Run Entry'!M16="","",'qPCR Run Entry'!M16) | Q16: =IF('qPCR Run Entry'!N16="","",'qPCR Run Entry'!N16) | R16: =IF('qPCR Run Entry'!O16="","",'qPCR Run Entry'!O16) | S16: IAC | T16: CALFL-ORNG | X16: =IF('qPCR Run Entry'!U16="","",'qPCR Run Entry'!U16) | Z16: =U16-Y16 -> 0 | AA16: =IF(ISNUMBER(Y16),IF(ABS(Z16)>1.5, "FAIL", "Pass"),"") | AC16: =O16 -> 0 | AD16: =IF('qPCR Run Entry'!X16="","",'qPCR Run Entry'!X16) | AE16: =IF('qPCR Run Entry'!Y16="","",'qPCR Run Entry'!Y16) | AF16: =IF('qPCR Run Entry'!Z16="","",'qPCR Run Entry'!Z16) | AG16: IAC | AH16: CALFL-ORNG | AL16: =IF('qPCR Run Entry'!AF16="","",'qPCR Run Entry'!AF16) | AN16: =AI16-AM16 -> 0 | AO16: =IF(ISNUMBER(AM16),IF(ABS(AN16)>1.5, "FAIL", "Pass"),"")
B17: =IF('qPCR Run Entry'!B17="","",'qPCR Run Entry'!B17) | C17: =IF('qPCR Run Entry'!C17="","",'qPCR Run Entry'!C17) | E17: IAC | F17: CALFL-ORNG | J17: =IF('qPCR Run Entry'!J17="","",'qPCR Run Entry'!J17) | L17: =G17-K17 -> 0 | M17: =IF(ISNUMBER(K17),IF(ABS(L17)>1.5, "FAIL", "Pass"),"") | P17: =IF('qPCR Run Entry'!M17="","",'qPCR Run Entry'!M17) | Q17: =IF('qPCR Run Entry'!N17="","",'qPCR Run Entry'!N17) | R17: =IF('qPCR Run Entry'!O17="","",'qPCR Run Entry'!O17) | S17: IAC | T17: CALFL-ORNG | X17: =IF('qPCR Run Entry'!U17="","",'qPCR Run Entry'!U17) | Z17: =U17-Y17 -> 0 | AA17: =IF(ISNUMBER(Y17),IF(ABS(Z17)>1.5, "FAIL", "Pass"),"") | AD17: =IF('qPCR Run Entry'!X17="","",'qPCR Run Entry'!X17) | AE17: =IF('qPCR Run Entry'!Y17="","",'qPCR Run Entry'!Y17) | AF17: =IF('qPCR Run Entry'!Z17="","",'qPCR Run Entry'!Z17) | AG17: IAC | AH17: CALFL-ORNG | AL17: =IF('qPCR Run Entry'!AF17="","",'qPCR Run Entry'!AF17) | AN17: =AI17-AM17 -> 0 | AO17: =IF(ISNUMBER(AM17),IF(ABS(AN17)>1.5, "FAIL", "Pass"),"")
A18: ='Sample Metadata'!D9 -> 0 | B18: =IF('qPCR Run Entry'!B18="","",'qPCR Run Entry'!B18) | C18: =IF('qPCR Run Entry'!C18="","",'qPCR Run Entry'!C18) | D18: =IF('qPCR Run Entry'!D18="","",'qPCR Run Entry'!D18) | E18: IAC | F18: CALFL-ORNG | J18: =IF('qPCR Run Entry'!J18="","",'qPCR Run Entry'!J18) | L18: =G18-K18 -> 0 | M18: =IF(ISNUMBER(K18),IF(ABS(L18)>1.5, "FAIL", "Pass"),"") | O18: =A18 -> 0 | P18: =IF('qPCR Run Entry'!M18="","",'qPCR Run Entry'!M18) | Q18: =IF('qPCR Run Entry'!N18="","",'qPCR Run Entry'!N18) | R18: =IF('qPCR Run Entry'!O18="","",'qPCR Run Entry'!O18) | S18: IAC | T18: CALFL-ORNG | X18: =IF('qPCR Run Entry'!U18="","",'qPCR Run Entry'!U18) | Z18: =U18-Y18 -> 0 | AA18: =IF(ISNUMBER(Y18),IF(ABS(Z18)>1.5, "FAIL", "Pass"),"") | AC18: =O18 -> 0 | AD18: =IF('qPCR Run Entry'!X18="","",'qPCR Run Entry'!X18) | AE18: =IF('qPCR Run Entry'!Y18="","",'qPCR Run Entry'!Y18) | AF18: =IF('qPCR Run Entry'!Z18="","",'qPCR Run Entry'!Z18) | AG18: IAC | AH18: CALFL-ORNG | AL18: =IF('qPCR Run Entry'!AF18="","",'qPCR Run Entry'!AF18) | AN18: =AI18-AM18 -> 0 | AO18: =IF(ISNUMBER(AM18),IF(ABS(AN18)>1.5, "FAIL", "Pass"),"")
B19: =IF('qPCR Run Entry'!B19="","",'qPCR Run Entry'!B19) | C19: =IF('qPCR Run Entry'!C19="","",'qPCR Run Entry'!C19) | E19: IAC | F19: CALFL-ORNG | J19: =IF('qPCR Run Entry'!J19="","",'qPCR Run Entry'!J19) | L19: =G19-K19 -> 0 | M19: =IF(ISNUMBER(K19),IF(ABS(L19)>1.5, "FAIL", "Pass"),"") | P19: =IF('qPCR Run Entry'!M19="","",'qPCR Run Entry'!M19) | Q19: =IF('qPCR Run Entry'!N19="","",'qPCR Run Entry'!N19) | R19: =IF('qPCR Run Entry'!O19="","",'qPCR Run Entry'!O19) | S19: IAC | T19: CALFL-ORNG | X19: =IF('qPCR Run Entry'!U19="","",'qPCR Run Entry'!U19) | Z19: =U19-Y19 -> 0 | AA19: =IF(ISNUMBER(Y19),IF(ABS(Z19)>1.5, "FAIL", "Pass"),"") | AD19: =IF('qPCR Run Entry'!X19="","",'qPCR Run Entry'!X19) | AE19: =IF('qPCR Run Entry'!Y19="","",'qPCR Run Entry'!Y19) | AF19: =IF('qPCR Run Entry'!Z19="","",'qPCR Run Entry'!Z19) | AG19: IAC | AH19: CALFL-ORNG | AL19: =IF('qPCR Run Entry'!AF19="","",'qPCR Run Entry'!AF19) | AN19: =AI19-AM19 -> 0 | AO19: =IF(ISNUMBER(AM19),IF(ABS(AN19)>1.5, "FAIL", "Pass"),"")
A20: ='Sample Metadata'!D10 -> 0 | B20: =IF('qPCR Run Entry'!B20="","",'qPCR Run Entry'!B20) | C20: =IF('qPCR Run Entry'!C20="","",'qPCR Run Entry'!C20) | D20: =IF('qPCR Run Entry'!D20="","",'qPCR Run Entry'!D20) | E20: IAC | F20: CALFL-ORNG | J20: =IF('qPCR Run Entry'!J20="","",'qPCR Run Entry'!J20) | L20: =G20-K20 -> 0 | M20: =IF(ISNUMBER(K20),IF(ABS(L20)>1.5, "FAIL", "Pass"),"") | O20: =A20 -> 0 | P20: =IF('qPCR Run Entry'!M20="","",'qPCR Run Entry'!M20) | Q20: =IF('qPCR Run Entry'!N20="","",'qPCR Run Entry'!N20) | R20: =IF('qPCR Run Entry'!O20="","",'qPCR Run Entry'!O20) | S20: IAC | T20: CALFL-ORNG | X20: =IF('qPCR Run Entry'!U20="","",'qPCR Run Entry'!U20) | Z20: =U20-Y20 -> 0 | AA20: =IF(ISNUMBER(Y20),IF(ABS(Z20)>1.5, "FAIL", "Pass"),"") | AC20: =O20 -> 0 | AD20: =IF('qPCR Run Entry'!X20="","",'qPCR Run Entry'!X20) | AE20: =IF('qPCR Run Entry'!Y20="","",'qPCR Run Entry'!Y20) | AF20: =IF('qPCR Run Entry'!Z20="","",'qPCR Run Entry'!Z20) | AG20: IAC | AH20: CALFL-ORNG | AL20: =IF('qPCR Run Entry'!AF20="","",'qPCR Run Entry'!AF20) | AN20: =AI20-AM20 -> 0 | AO20: =IF(ISNUMBER(AM20),IF(ABS(AN20)>1.5, "FAIL", "Pass"),"")
B21: =IF('qPCR Run Entry'!B21="","",'qPCR Run Entry'!B21) | C21: =IF('qPCR Run Entry'!C21="","",'qPCR Run Entry'!C21) | E21: IAC | F21: CALFL-ORNG | J21: =IF('qPCR Run Entry'!J21="","",'qPCR Run Entry'!J21) | L21: =G21-K21 -> 0 | M21: =IF(ISNUMBER(K21),IF(ABS(L21)>1.5, "FAIL", "Pass"),"") | P21: =IF('qPCR Run Entry'!M21="","",'qPCR Run Entry'!M21) | Q21: =IF('qPCR Run Entry'!N21="","",'qPCR Run Entry'!N21) | R21: =IF('qPCR Run Entry'!O21="","",'qPCR Run Entry'!O21) | S21: IAC | T21: CALFL-ORNG | X21: =IF('qPCR Run Entry'!U21="","",'qPCR Run Entry'!U21) | Z21: =U21-Y21 -> 0 | AA21: =IF(ISNUMBER(Y21),IF(ABS(Z21)>1.5, "FAIL", "Pass"),"") | AD21: =IF('qPCR Run Entry'!X21="","",'qPCR Run Entry'!X21) | AE21: =IF('qPCR Run Entry'!Y21="","",'qPCR Run Entry'!Y21) | AF21: =IF('qPCR Run Entry'!Z21="","",'qPCR Run Entry'!Z21) | AG21: IAC | AH21: CALFL-ORNG | AL21: =IF('qPCR Run Entry'!AF21="","",'qPCR Run Entry'!AF21) | AN21: =AI21-AM21 -> 0 | AO21: =IF(ISNUMBER(AM21),IF(ABS(AN21)>1.5, "FAIL", "Pass"),"")
A22: ='Sample Metadata'!D11 -> 0 | B22: =IF('qPCR Run Entry'!B22="","",'qPCR Run Entry'!B22) | C22: =IF('qPCR Run Entry'!C22="","",'qPCR Run Entry'!C22) | D22: =IF('qPCR Run Entry'!D22="","",'qPCR Run Entry'!D22) | E22: IAC | F22: CALFL-ORNG | J22: =IF('qPCR Run Entry'!J22="","",'qPCR Run Entry'!J22) | L22: =G22-K22 -> 0 | M22: =IF(ISNUMBER(K22),IF(ABS(L22)>1.5, "FAIL", "Pass"),"") | O22: =A22 -> 0 | P22: =IF('qPCR Run Entry'!M22="","",'qPCR Run Entry'!M22) | Q22: =IF('qPCR Run Entry'!N22="","",'qPCR Run Entry'!N22) | R22: =IF('qPCR Run Entry'!O22="","",'qPCR Run Entry'!O22) | S22: IAC | T22: CALFL-ORNG | X22: =IF('qPCR Run Entry'!U22="","",'qPCR Run Entry'!U22) | Z22: =U22-Y22 -> 0 | AA22: =IF(ISNUMBER(Y22),IF(ABS(Z22)>1.5, "FAIL", "Pass"),"") | AC22: =O22 -> 0 | AD22: =IF('qPCR Run Entry'!X22="","",'qPCR Run Entry'!X22) | AE22: =IF('qPCR Run Entry'!Y22="","",'qPCR Run Entry'!Y22) | AF22: =IF('qPCR Run Entry'!Z22="","",'qPCR Run Entry'!Z22) | AG22: IAC | AH22: CALFL-ORNG | AL22: =IF('qPCR Run Entry'!AF22="","",'qPCR Run Entry'!AF22) | AN22: =AI22-AM22 -> 0 | AO22: =IF(ISNUMBER(AM22),IF(ABS(AN22)>1.5, "FAIL", "Pass"),"")
B23: =IF('qPCR Run Entry'!B23="","",'qPCR Run Entry'!B23) | C23: =IF('qPCR Run Entry'!C23="","",'qPCR Run Entry'!C23) | E23: IAC | F23: CALFL-ORNG | J23: =IF('qPCR Run Entry'!J23="","",'qPCR Run Entry'!J23) | L23: =G23-K23 -> 0 | M23: =IF(ISNUMBER(K23),IF(ABS(L23)>1.5, "FAIL", "Pass"),"") | P23: =IF('qPCR Run Entry'!M23="","",'qPCR Run Entry'!M23) | Q23: =IF('qPCR Run Entry'!N23="","",'qPCR Run Entry'!N23) | R23: =IF('qPCR Run Entry'!O23="","",'qPCR Run Entry'!O23) | S23: IAC | T23: CALFL-ORNG | X23: =IF('qPCR Run Entry'!U23="","",'qPCR Run Entry'!U23) | Z23: =U23-Y23 -> 0 | AA23: =IF(ISNUMBER(Y23),IF(ABS(Z23)>1.5, "FAIL", "Pass"),"") | AD23: =IF('qPCR Run Entry'!X23="","",'qPCR Run Entry'!X23) | AE23: =IF('qPCR Run Entry'!Y23="","",'qPCR Run Entry'!Y23) | AF23: =IF('qPCR Run Entry'!Z23="","",'qPCR Run Entry'!Z23) | AG23: IAC | AH23: CALFL-ORNG | AL23: =IF('qPCR Run Entry'!AF23="","",'qPCR Run Entry'!AF23) | AN23: =AI23-AM23 -> 0 | AO23: =IF(ISNUMBER(AM23),IF(ABS(AN23)>1.5, "FAIL", "Pass"),"")
A24: ='Sample Metadata'!D12 -> 0 | B24: =IF('qPCR Run Entry'!B24="","",'qPCR Run Entry'!B24) | C24: =IF('qPCR Run Entry'!C24="","",'qPCR Run Entry'!C24) | D24: =IF('qPCR Run Entry'!D24="","",'qPCR Run Entry'!D24) | E24: IAC | F24: CALFL-ORNG | J24: =IF('qPCR Run Entry'!J24="","",'qPCR Run Entry'!J24) | L24: =G24-K24 -> 0 | M24: =IF(ISNUMBER(K24),IF(ABS(L24)>1.5, "FAIL", "Pass"),"") | O24: =A24 -> 0 | P24: =IF('qPCR Run Entry'!M24="","",'qPCR Run Entry'!M24) | Q24: =IF('qPCR Run Entry'!N24="","",'qPCR Run Entry'!N24) | R24: =IF('qPCR Run Entry'!O24="","",'qPCR Run Entry'!O24) | S24: IAC | T24: CALFL-ORNG | X24: =IF('qPCR Run Entry'!U24="","",'qPCR Run Entry'!U24) | Z24: =U24-Y24 -> 0 | AA24: =IF(ISNUMBER(Y24),IF(ABS(Z24)>1.5, "FAIL", "Pass"),"") | AC24: =O24 -> 0 | AD24: =IF('qPCR Run Entry'!X24="","",'qPCR Run Entry'!X24) | AE24: =IF('qPCR Run Entry'!Y24="","",'qPCR Run Entry'!Y24) | AF24: =IF('qPCR Run Entry'!Z24="","",'qPCR Run Entry'!Z24) | AG24: IAC | AH24: CALFL-ORNG | AL24: =IF('qPCR Run Entry'!AF24="","",'qPCR Run Entry'!AF24) | AN24: =AI24-AM24 -> 0 | AO24: =IF(ISNUMBER(AM24),IF(ABS(AN24)>1.5, "FAIL", "Pass"),"")
B25: =IF('qPCR Run Entry'!B25="","",'qPCR Run Entry'!B25) | C25: =IF('qPCR Run Entry'!C25="","",'qPCR Run Entry'!C25) | E25: IAC | F25: CALFL-ORNG | J25: =IF('qPCR Run Entry'!J25="","",'qPCR Run Entry'!J25) | L25: =G25-K25 -> 0 | M25: =IF(ISNUMBER(K25),IF(ABS(L25)>1.5, "FAIL", "Pass"),"") | P25: =IF('qPCR Run Entry'!M25="","",'qPCR Run Entry'!M25) | Q25: =IF('qPCR Run Entry'!N25="","",'qPCR Run Entry'!N25) | R25: =IF('qPCR Run Entry'!O25="","",'qPCR Run Entry'!O25) | S25: IAC | T25: CALFL-ORNG | X25: =IF('qPCR Run Entry'!U25="","",'qPCR Run Entry'!U25) | Z25: =U25-Y25 -> 0 | AA25: =IF(ISNUMBER(Y25),IF(ABS(Z25)>1.5, "FAIL", "Pass"),"") | AD25: =IF('qPCR Run Entry'!X25="","",'qPCR Run Entry'!X25) | AE25: =IF('qPCR Run Entry'!Y25="","",'qPCR Run Entry'!Y25) | AF25: =IF('qPCR Run Entry'!Z25="","",'qPCR Run Entry'!Z25) | AG25: IAC | AH25: CALFL-ORNG | AL25: =IF('qPCR Run Entry'!AF25="","",'qPCR Run Entry'!AF25) | AN25: =AI25-AM25 -> 0 | AO25: =IF(ISNUMBER(AM25),IF(ABS(AN25)>1.5, "FAIL", "Pass"),"")
A26: ='Sample Metadata'!D13 -> 0 | B26: =IF('qPCR Run Entry'!B26="","",'qPCR Run Entry'!B26) | C26: =IF('qPCR Run Entry'!C26="","",'qPCR Run Entry'!C26) | D26: =IF('qPCR Run Entry'!D26="","",'qPCR Run Entry'!D26) | E26: IAC | F26: CALFL-ORNG | J26: =IF('qPCR Run Entry'!J26="","",'qPCR Run Entry'!J26) | L26: =G26-K26 -> 0 | M26: =IF(ISNUMBER(K26),IF(ABS(L26)>1.5, "FAIL", "Pass"),"") | O26: =A26 -> 0 | P26: =IF('qPCR Run Entry'!M26="","",'qPCR Run Entry'!M26) | Q26: =IF('qPCR Run Entry'!N26="","",'qPCR Run Entry'!N26) | R26: =IF('qPCR Run Entry'!O26="","",'qPCR Run Entry'!O26) | S26: IAC | T26: CALFL-ORNG | X26: =IF('qPCR Run Entry'!U26="","",'qPCR Run Entry'!U26) | Z26: =U26-Y26 -> 0 | AA26: =IF(ISNUMBER(Y26),IF(ABS(Z26)>1.5, "FAIL", "Pass"),"") | AC26: =O26 -> 0 | AD26: =IF('qPCR Run Entry'!X26="","",'qPCR Run Entry'!X26) | AE26: =IF('qPCR Run Entry'!Y26="","",'qPCR Run Entry'!Y26) | AF26: =IF('qPCR Run Entry'!Z26="","",'qPCR Run Entry'!Z26) | AG26: IAC | AH26: CALFL-ORNG | AL26: =IF('qPCR Run Entry'!AF26="","",'qPCR Run Entry'!AF26) | AN26: =AI26-AM26 -> 0 | AO26: =IF(ISNUMBER(AM26),IF(ABS(AN26)>1.5, "FAIL", "Pass"),"")
B27: =IF('qPCR Run Entry'!B27="","",'qPCR Run Entry'!B27) | C27: =IF('qPCR Run Entry'!C27="","",'qPCR Run Entry'!C27) | E27: IAC | F27: CALFL-ORNG | J27: =IF('qPCR Run Entry'!J27="","",'qPCR Run Entry'!J27) | L27: =G27-K27 -> 0 | M27: =IF(ISNUMBER(K27),IF(ABS(L27)>1.5, "FAIL", "Pass"),"") | P27: =IF('qPCR Run Entry'!M27="","",'qPCR Run Entry'!M27) | Q27: =IF('qPCR Run Entry'!N27="","",'qPCR Run Entry'!N27) | R27: =IF('qPCR Run Entry'!O27="","",'qPCR Run Entry'!O27) | S27: IAC | T27: CALFL-ORNG | X27: =IF('qPCR Run Entry'!U27="","",'qPCR Run Entry'!U27) | Z27: =U27-Y27 -> 0 | AA27: =IF(ISNUMBER(Y27),IF(ABS(Z27)>1.5, "FAIL", "Pass"),"") | AD27: =IF('qPCR Run Entry'!X27="","",'qPCR Run Entry'!X27) | AE27: =IF('qPCR Run Entry'!Y27="","",'qPCR Run Entry'!Y27) | AF27: =IF('qPCR Run Entry'!Z27="","",'qPCR Run Entry'!Z27) | AG27: IAC | AH27: CALFL-ORNG | AL27: =IF('qPCR Run Entry'!AF27="","",'qPCR Run Entry'!AF27) | AN27: =AI27-AM27 -> 0 | AO27: =IF(ISNUMBER(AM27),IF(ABS(AN27)>1.5, "FAIL", "Pass"),"")
A28: ='Sample Metadata'!D14 -> 0 | B28: =IF('qPCR Run Entry'!B28="","",'qPCR Run Entry'!B28) | C28: =IF('qPCR Run Entry'!C28="","",'qPCR Run Entry'!C28) | D28: =IF('qPCR Run Entry'!D28="","",'qPCR Run Entry'!D28) | E28: IAC | F28: CALFL-ORNG | J28: =IF('qPCR Run Entry'!J28="","",'qPCR Run Entry'!J28) | L28: =G28-K28 -> 0 | M28: =IF(ISNUMBER(K28),IF(ABS(L28)>1.5, "FAIL", "Pass"),"") | O28: =A28 -> 0 | P28: =IF('qPCR Run Entry'!M28="","",'qPCR Run Entry'!M28) | Q28: =IF('qPCR Run Entry'!N28="","",'qPCR Run Entry'!N28) | R28: =IF('qPCR Run Entry'!O28="","",'qPCR Run Entry'!O28) | S28: IAC | T28: CALFL-ORNG | X28: =IF('qPCR Run Entry'!U28="","",'qPCR Run Entry'!U28) | Z28: =U28-Y28 -> 0 | AA28: =IF(ISNUMBER(Y28),IF(ABS(Z28)>1.5, "FAIL", "Pass"),"") | AC28: =O28 -> 0 | AD28: =IF('qPCR Run Entry'!X28="","",'qPCR Run Entry'!X28) | AE28: =IF('qPCR Run Entry'!Y28="","",'qPCR Run Entry'!Y28) | AF28: =IF('qPCR Run Entry'!Z28="","",'qPCR Run Entry'!Z28) | AG28: IAC | AH28: CALFL-ORNG | AL28: =IF('qPCR Run Entry'!AF28="","",'qPCR Run Entry'!AF28) | AN28: =AI28-AM28 -> 0 | AO28: =IF(ISNUMBER(AM28),IF(ABS(AN28)>1.5, "FAIL", "Pass"),"")
B29: =IF('qPCR Run Entry'!B29="","",'qPCR Run Entry'!B29) | C29: =IF('qPCR Run Entry'!C29="","",'qPCR Run Entry'!C29) | E29: IAC | F29: CALFL-ORNG | J29: =IF('qPCR Run Entry'!J29="","",'qPCR Run Entry'!J29) | L29: =G29-K29 -> 0 | M29: =IF(ISNUMBER(K29),IF(ABS(L29)>1.5, "FAIL", "Pass"),"") | P29: =IF('qPCR Run Entry'!M29="","",'qPCR Run Entry'!M29) | Q29: =IF('qPCR Run Entry'!N29="","",'qPCR Run Entry'!N29) | R29: =IF('qPCR Run Entry'!O29="","",'qPCR Run Entry'!O29) | S29: IAC | T29: CALFL-ORNG | X29: =IF('qPCR Run Entry'!U29="","",'qPCR Run Entry'!U29) | Z29: =U29-Y29 -> 0 | AA29: =IF(ISNUMBER(Y29),IF(ABS(Z29)>1.5, "FAIL", "Pass"),"") | AD29: =IF('qPCR Run Entry'!X29="","",'qPCR Run Entry'!X29) | AE29: =IF('qPCR Run Entry'!Y29="","",'qPCR Run Entry'!Y29) | AF29: =IF('qPCR Run Entry'!Z29="","",'qPCR Run Entry'!Z29) | AG29: IAC | AH29: CALFL-ORNG | AL29: =IF('qPCR Run Entry'!AF29="","",'qPCR Run Entry'!AF29) | AN29: =AI29-AM29 -> 0 | AO29: =IF(ISNUMBER(AM29),IF(ABS(AN29)>1.5, "FAIL", "Pass"),"")
A30: ='Sample Metadata'!D15 -> 0 | B30: =IF('qPCR Run Entry'!B30="","",'qPCR Run Entry'!B30) | C30: =IF('qPCR Run Entry'!C30="","",'qPCR Run Entry'!C30) | D30: =IF('qPCR Run Entry'!D30="","",'qPCR Run Entry'!D30) | E30: IAC | F30: CALFL-ORNG | J30: =IF('qPCR Run Entry'!J30="","",'qPCR Run Entry'!J30) | L30: =G30-K30 -> 0 | M30: =IF(ISNUMBER(K30),IF(ABS(L30)>1.5, "FAIL", "Pass"),"") | O30: =A30 -> 0 | P30: =IF('qPCR Run Entry'!M30="","",'qPCR Run Entry'!M30) | Q30: =IF('qPCR Run Entry'!N30="","",'qPCR Run Entry'!N30) | R30: =IF('qPCR Run Entry'!O30="","",'qPCR Run Entry'!O30) | S30: IAC | T30: CALFL-ORNG | X30: =IF('qPCR Run Entry'!U30="","",'qPCR Run Entry'!U30) | Z30: =U30-Y30 -> 0 | AA30: =IF(ISNUMBER(Y30),IF(ABS(Z30)>1.5, "FAIL", "Pass"),"") | AC30: =O30 -> 0 | AD30: =IF('qPCR Run Entry'!X30="","",'qPCR Run Entry'!X30) | AE30: =IF('qPCR Run Entry'!Y30="","",'qPCR Run Entry'!Y30) | AF30: =IF('qPCR Run Entry'!Z30="","",'qPCR Run Entry'!Z30) | AG30: IAC | AH30: CALFL-ORNG | AL30: =IF('qPCR Run Entry'!AF30="","",'qPCR Run Entry'!AF30) | AN30: =AI30-AM30 -> 0 | AO30: =IF(ISNUMBER(AM30),IF(ABS(AN30)>1.5, "FAIL", "Pass"),"")
B31: =IF('qPCR Run Entry'!B31="","",'qPCR Run Entry'!B31) | C31: =IF('qPCR Run Entry'!C31="","",'qPCR Run Entry'!C31) | E31: IAC | F31: CALFL-ORNG | J31: =IF('qPCR Run Entry'!J31="","",'qPCR Run Entry'!J31) | L31: =G31-K31 -> 0 | M31: =IF(ISNUMBER(K31),IF(ABS(L31)>1.5, "FAIL", "Pass"),"") | P31: =IF('qPCR Run Entry'!M31="","",'qPCR Run Entry'!M31) | Q31: =IF('qPCR Run Entry'!N31="","",'qPCR Run Entry'!N31) | R31: =IF('qPCR Run Entry'!O31="","",'qPCR Run Entry'!O31) | S31: IAC | T31: CALFL-ORNG | X31: =IF('qPCR Run Entry'!U31="","",'qPCR Run Entry'!U31) | Z31: =U31-Y31 -> 0 | AA31: =IF(ISNUMBER(Y31),IF(ABS(Z31)>1.5, "FAIL", "Pass"),"") | AD31: =IF('qPCR Run Entry'!X31="","",'qPCR Run Entry'!X31) | AE31: =IF('qPCR Run Entry'!Y31="","",'qPCR Run Entry'!Y31) | AF31: =IF('qPCR Run Entry'!Z31="","",'qPCR Run Entry'!Z31) | AG31: IAC | AH31: CALFL-ORNG | AL31: =IF('qPCR Run Entry'!AF31="","",'qPCR Run Entry'!AF31) | AN31: =AI31-AM31 -> 0 | AO31: =IF(ISNUMBER(AM31),IF(ABS(AN31)>1.5, "FAIL", "Pass"),"")
A32: ='Sample Metadata'!D16 -> 0 | B32: =IF('qPCR Run Entry'!B32="","",'qPCR Run Entry'!B32) | C32: =IF('qPCR Run Entry'!C32="","",'qPCR Run Entry'!C32) | D32: =IF('qPCR Run Entry'!D32="","",'qPCR Run Entry'!D32) | E32: IAC | F32: CALFL-ORNG | J32: =IF('qPCR Run Entry'!J32="","",'qPCR Run Entry'!J32) | L32: =G32-K32 -> 0 | M32: =IF(ISNUMBER(K32),IF(ABS(L32)>1.5, "FAIL", "Pass"),"") | O32: =A32 -> 0 | P32: =IF('qPCR Run Entry'!M32="","",'qPCR Run Entry'!M32) | Q32: =IF('qPCR Run Entry'!N32="","",'qPCR Run Entry'!N32) | R32: =IF('qPCR Run Entry'!O32="","",'qPCR Run Entry'!O32) | S32: IAC | T32: CALFL-ORNG | X32: =IF('qPCR Run Entry'!U32="","",'qPCR Run Entry'!U32) | Z32: =U32-Y32 -> 0 | AA32: =IF(ISNUMBER(Y32),IF(ABS(Z32)>1.5, "FAIL", "Pass"),"") | AC32: =O32 -> 0 | AD32: =IF('qPCR Run Entry'!X32="","",'qPCR Run Entry'!X32) | AE32: =IF('qPCR Run Entry'!Y32="","",'qPCR Run Entry'!Y32) | AF32: =IF('qPCR Run Entry'!Z32="","",'qPCR Run Entry'!Z32) | AG32: IAC | AH32: CALFL-ORNG | AL32: =IF('qPCR Run Entry'!AF32="","",'qPCR Run Entry'!AF32) | AN32: =AI32-AM32 -> 0 | AO32: =IF(ISNUMBER(AM32),IF(ABS(AN32)>1.5, "FAIL", "Pass"),"")
B33: =IF('qPCR Run Entry'!B33="","",'qPCR Run Entry'!B33) | C33: =IF('qPCR Run Entry'!C33="","",'qPCR Run Entry'!C33) | E33: IAC | F33: CALFL-ORNG | J33: =IF('qPCR Run Entry'!J33="","",'qPCR Run Entry'!J33) | L33: =G33-K33 -> 0 | M33: =IF(ISNUMBER(K33),IF(ABS(L33)>1.5, "FAIL", "Pass"),"") | P33: =IF('qPCR Run Entry'!M33="","",'qPCR Run Entry'!M33) | Q33: =IF('qPCR Run Entry'!N33="","",'qPCR Run Entry'!N33) | R33: =IF('qPCR Run Entry'!O33="","",'qPCR Run Entry'!O33) | S33: IAC | T33: CALFL-ORNG | X33: =IF('qPCR Run Entry'!U33="","",'qPCR Run Entry'!U33) | Z33: =U33-Y33 -> 0 | AA33: =IF(ISNUMBER(Y33),IF(ABS(Z33)>1.5, "FAIL", "Pass"),"") | AD33: =IF('qPCR Run Entry'!X33="","",'qPCR Run Entry'!X33) | AE33: =IF('qPCR Run Entry'!Y33="","",'qPCR Run Entry'!Y33) | AF33: =IF('qPCR Run Entry'!Z33="","",'qPCR Run Entry'!Z33) | AG33: IAC | AH33: CALFL-ORNG | AL33: =IF('qPCR Run Entry'!AF33="","",'qPCR Run Entry'!AF33) | AN33: =AI33-AM33 -> 0 | AO33: =IF(ISNUMBER(AM33),IF(ABS(AN33)>1.5, "FAIL", "Pass"),"")
A34: ='Sample Metadata'!D17 -> 0 | B34: =IF('qPCR Run Entry'!B34="","",'qPCR Run Entry'!B34) | C34: =IF('qPCR Run Entry'!C34="","",'qPCR Run Entry'!C34) | D34: =IF('qPCR Run Entry'!D34="","",'qPCR Run Entry'!D34) | E34: IAC | F34: CALFL-ORNG | J34: =IF('qPCR Run Entry'!J34="","",'qPCR Run Entry'!J34) | L34: =G34-K34 -> 0 | M34: =IF(ISNUMBER(K34),IF(ABS(L34)>1.5, "FAIL", "Pass"),"") | O34: =A34 -> 0 | P34: =IF('qPCR Run Entry'!M34="","",'qPCR Run Entry'!M34) | Q34: =IF('qPCR Run Entry'!N34="","",'qPCR Run Entry'!N34) | R34: =IF('qPCR Run Entry'!O34="","",'qPCR Run Entry'!O34) | S34: IAC | T34: CALFL-ORNG | X34: =IF('qPCR Run Entry'!U34="","",'qPCR Run Entry'!U34) | Z34: =U34-Y34 -> 0 | AA34: =IF(ISNUMBER(Y34),IF(ABS(Z34)>1.5, "FAIL", "Pass"),"") | AC34: =O34 -> 0 | AD34: =IF('qPCR Run Entry'!X34="","",'qPCR Run Entry'!X34) | AE34: =IF('qPCR Run Entry'!Y34="","",'qPCR Run Entry'!Y34) | AF34: =IF('qPCR Run Entry'!Z34="","",'qPCR Run Entry'!Z34) | AG34: IAC | AH34: CALFL-ORNG | AL34: =IF('qPCR Run Entry'!AF34="","",'qPCR Run Entry'!AF34) | AN34: =AI34-AM34 -> 0 | AO34: =IF(ISNUMBER(AM34),IF(ABS(AN34)>1.5, "FAIL", "Pass"),"")
